Workbook
Name _Hlk49843120: 'RESULTS Eversource'!#REF!
Name _Hlk50967569: 'RESULTS Eversource'!$A$8

Sheet INSTRUCTIONS
A1: INSTRUCTIONS - INDIVIDUAL EEMS | B1: INSTRUCTIONS - PACKAGE OF EEMS
A2: 1) Enter all EEM data ine the "EEM Data Entry" tab, including title, capital cost, estimated kWh savings for electric and MMBtu savings for each fuel type, and measure lifetime | B2: 1) Enter all EEM data FOR PACKAGE ONLY, including title, capital cost, estimated savings percent for each fuel type, and measure lifetime. ENTER PACKAGE TITLE WHERE INDICATED
A3: 2) Follow the instructions on the "Interest Rate" tab to determine the interest rate for this project | B3: 2) Follow the instructions on the "Interest Rate" tab to determine the interest rate for this project
A4: 3) Copy and paste tables from the appropriate "RESULTS" tab to audit report | B4: 3) Copy and paste THE PACKAGE TABLE to report as appropriate
A6: Cell Color-Coding Key
A7: Data Entry
A8: Formula (optional override but should not be necessary)
A10: Tab Color-Coding Key
A11: Reference
A12: Data Entry
A13: Results
A14: Backend - Individual EEMs
A15: Backend - Package & Cascading

Sheet EEM Data Entry
H1: ENTER KWH AND MMBTU SAVINGS VALUES NOT PERCENTAGES
A2: EEM Info | D2: Capital Cost | H2: Energy Savings | S2: 3.412142 | U2: 137.381 | W2: 100 | Y2: 91.5 | AC2: 16400 | AE2: 9500
A3: EEM # | B3: EEM Title | C3: Lifetime of Measure | D3: Capital Cost | E3: Incentive/ Rebate (ENTER "0" IF N/A) | F3: Final Installed Cost | G3: Incentive Reference | H3: Electric kWh | I3: Oil MMBtu | J3: Natural Gas MMBtu | K3: Propane MMBtu | L3: District Steam | M3: Wood Pellets MMBtu | N3: Wood Chips MMBtu | O3: Water | Q3: ENTER ASSUMPTIONS HERE
B4: Envelope | R4: Assumptions | S4: Electricity | U4: Fuel Oil | W4: Natural Gas | Y4: Propane | AA4: District Steam | AC4: Wood Pellets | AE4: Wood Chips | AG4: Water / Sewer | AI4: Total Energy
F5: =IF(AND(COUNT(D5)>0,COUNT(E5)>0),D5-E5,"") | G5: N/A | R5: Baseline Energy Usage: | S5: 0 | T5: kWh | U5: 0 | V5: Gallons | W5: 0 | X5: Therms | Y5: 0 | Z5: gallons | AA5: 0 | AB5: kPounds | AC5: 0 | AD5: tons | AE5: 0 | AF5: tons | AG5: 0 | AH5: kGallons | AI5: =SUM((S5*S2),(U2*U5),(W2*W5),(Y2*Y5),(AC2*AC5),(AE2*AE5)) -> 0 | AJ5: kBTU
F6: =IF(AND(COUNT(D6)>0,COUNT(E6)>0),D6-E6,"") | G6: N/A | R6: Baseline Annual Energy Cost: | S6: 0 | T6: Cost | U6: 0 | V6: Cost | W6: 0 | X6: Cost | Y6: 0 | Z6: Cost | AA6: 0 | AB6: Cost | AC6: 0 | AD6: Cost | AE6: 0 | AF6: Cost | AG6: 0 | AH6: Cost | AI6: =S6+U6+W6+Y6+AA6+AE6+AG6+AC6 -> 0 | AJ6: Total Cost
F7: =IF(AND(COUNT(D7)>0,COUNT(E7)>0),D7-E7,"") | G7: N/A | R7: Baseline Unit Cost: | S7: =IF(S5=0,0,S6/S5) -> 0 | T7: ($/kWh) | U7: =IF(U5=0,0,U6/U5) -> 0 | V7: ($/gal.) | W7: =IF(W5=0,0,W6/W5) -> 0 | X7: ($/therm) | Y7: =IF(Y5=0,0,Y6/Y5) -> 0 | Z7: ($/gal.) | AA7: =IF(AA5=0,0,AA6/AA5) -> 0 | AB7: ($/kLbs..) | AC7: =IF(AC5=0,0,AC6/AC5) -> 0 | AD7: ($/ton) | AE7: =IF(AE5=0,0,AE6/AE5) -> 0 | AF7: ($/ton) | AG7: =IF(AG5=0,0,AG6/AG5) -> 0 | AH7: ($/gal.)
F8: =IF(AND(COUNT(D8)>0,COUNT(E8)>0),D8-E8,"") | G8: N/A | R8: MMBtus | S8: =S5*0.003412142 -> 0 | T8: MMBtu | U8: =U5*0.137381 -> 0 | V8: MMBtu | W8: =W5*0.1 -> 0 | X8: MMBtu | Y8: =Y5*0.0915 -> 0 | Z8: MMBtu | AA8: =AA5*1.194 -> 0 | AB8: MMBtu | AC8: =AC5*16.4 -> 0 | AD8: MMBtu | AE8: =AE5*9.5 -> 0 | AF8: MMBtu
F9: =IF(AND(COUNT(D9)>0,COUNT(E9)>0),D9-E9,"") | G9: N/A | Q9: IF THIS IS AN EEM PACKAGE… | R9: $/MMBtu | S9: =S6/S8 -> #DIV/0! | T9: $/MMBtu | U9: =U6/U8 -> #DIV/0! | V9: $/MMBtu | W9: =W6/W8 -> #DIV/0! | X9: $/MMBtu | Y9: =Y6/Y8 -> #DIV/0! | Z9: $/MMBtu | AA9: =AA6/AA8 -> #DIV/0! | AB9: $/MMBtu | AC9: =AC6/AC8 -> #DIV/0! | AD9: $/MMBtu | AE9: =AE6/AE8 -> #DIV/0! | AF9: $/MMBtu
F10: =IF(AND(COUNT(D10)>0,COUNT(E10)>0),D10-E10,"") | G10: N/A
F11: =IF(AND(COUNT(D11)>0,COUNT(E11)>0),D11-E11,"") | G11: N/A
F12: =IF(AND(COUNT(D12)>0,COUNT(E12)>0),D12-E12,"") | G12: N/A
F13: =IF(AND(COUNT(D13)>0,COUNT(E13)>0),D13-E13,"") | G13: N/A | Q13: ENTER NAME OF PACKAGE IN THE BOX BELOW
F14: =IF(AND(COUNT(D14)>0,COUNT(E14)>0),D14-E14,"") | G14: N/A
F15: =IF(AND(COUNT(D15)>0,COUNT(E15)>0),D15-E15,"") | G15: N/A
F16: =IF(AND(COUNT(D16)>0,COUNT(E16)>0),D16-E16,"") | G16: N/A
F17: =IF(AND(COUNT(D17)>0,COUNT(E17)>0),D17-E17,"") | G17: N/A | Q17: RECOMMENDED PACKAGE: Example
F18: =IF(AND(COUNT(D18)>0,COUNT(E18)>0),D18-E18,"") | G18: N/A
F19: =IF(AND(COUNT(D19)>0,COUNT(E19)>0),D19-E19,"") | G19: N/A | Q19: AVERAGE BUILDING LIFESPAN ASSUMPTION
F20: =IF(AND(COUNT(D20)>0,COUNT(E20)>0),D20-E20,"") | G20: N/A
F21: =IF(AND(COUNT(D21)>0,COUNT(E21)>0),D21-E21,"") | G21: N/A
F22: =IF(AND(COUNT(D22)>0,COUNT(E22)>0),D22-E22,"") | G22: N/A | Q22: Average building lifespan = | R22: 63 | S22: SOURCE
F23: =IF(AND(COUNT(D23)>0,COUNT(E23)>0),D23-E23,"") | G23: N/A
F24: =IF(AND(COUNT(D24)>0,COUNT(E24)>0),D24-E24,"") | G24: N/A
F25: =IF(AND(COUNT(D25)>0,COUNT(E25)>0),D25-E25,"") | G25: N/A
F26: =IF(AND(COUNT(D26)>0,COUNT(E26)>0),D26-E26,"") | G26: N/A
F27: =IF(AND(COUNT(D27)>0,COUNT(E27)>0),D27-E27,"") | G27: N/A
F28: =IF(AND(COUNT(D28)>0,COUNT(E28)>0),D28-E28,"") | G28: N/A
B29: Mechanical
F30: =IF(AND(COUNT(D30)>0,COUNT(E30)>0),D30-E30,"") | G30: N/A
F31: =IF(AND(COUNT(D31)>0,COUNT(E31)>0),D31-E31,"") | G31: N/A
F32: =IF(AND(COUNT(D32)>0,COUNT(E32)>0),D32-E32,"") | G32: N/A
F33: =IF(AND(COUNT(D33)>0,COUNT(E33)>0),D33-E33,"") | G33: N/A
F34: =IF(AND(COUNT(D34)>0,COUNT(E34)>0),D34-E34,"") | G34: N/A
F35: =IF(AND(COUNT(D35)>0,COUNT(E35)>0),D35-E35,"") | G35: N/A
F36: =IF(AND(COUNT(D36)>0,COUNT(E36)>0),D36-E36,"") | G36: N/A
F37: =IF(AND(COUNT(D37)>0,COUNT(E37)>0),D37-E37,"") | G37: N/A
F38: =IF(AND(COUNT(D38)>0,COUNT(E38)>0),D38-E38,"") | G38: N/A
F39: =IF(AND(COUNT(D39)>0,COUNT(E39)>0),D39-E39,"") | G39: N/A
F40: =IF(AND(COUNT(D40)>0,COUNT(E40)>0),D40-E40,"") | G40: N/A
...

Sheet EEM Lifetimes
A1: Category | B1: Measure | C1: Measure Lifetime Ranges | D1: Current Averages | E1: Source 1 | F1: Source 2 | G1: Source 3 | L1: GENERAL SOURCE
A2: ADHESIVES, CAULK & PAINTS | B2: Caulking (interior & exterior) | C2: 10 | D2: 10
A3: ADHESIVES, CAULK & PAINTS | B3: Construction Glue | C3: 20+ | D3: 20 | L3: AVERAGE BUILDING LIFESPAN ASSUMPTION
A4: ADHESIVES, CAULK & PAINTS | B4: Roofing Adhesives/Cements | C4: 15+ | D4: 15
A5: ADHESIVES, CAULK & PAINTS | B5: Sealants | C5: 8 | D5: 8
A6: APPLIANCES | B6: Air Conditioner (window) | C6: 5 to 7 | D6: 10 | E6: 7 to 12 | F6: 15 yrs | L6: Average building lifespan = | M6: 63 | N6: SOURCE
A7: APPLIANCES | B7: Dehumidifier | C7: 8 | D7: 8
A8: APPLIANCES | B8: Dishwasher | C8: 9 | D8: 12 | E8: 9 to 11 | F8: 15
A9: APPLIANCES | B9: Dryer (clothes) | C9: 13 | D9: 13 | E9: 12 to 13 | F9: 8 to 18
A10: APPLIANCES | B10: Electric Range | C10: 13 to 15 | D10: 14 | E10: 13 to 16 | F10: 17 | G10: Commercial 12
A11: APPLIANCES | B11: Freezer | C11: 10 to 20 | D11: 15 | E11: 15
A12: APPLIANCES | B12: Gas Oven | C12: 10 to 18 | D12: 14
A13: APPLIANCES | B13: Gas Range | C13: 15 to 17 | D13: 15 | E13: 15 to 18 | F13: 15 | G13: Commercial 12
A14: APPLIANCES | B14: Hand Dryer | C14: 10 to 12 | D14: 11
A15: APPLIANCES | B15: Humidifier (portable) | C15: 8 | D15: 8
A16: APPLIANCES | B16: Microwave Oven | C16: 9 | D16: 9 | E16: 9 to 10
A17: APPLIANCES | B17: Range/Oven Hood | C17: 14 | D17: 14
A18: APPLIANCES | B18: Refrigerator | C18: 12 | D18: 14 | E18: SOURCE | F18: 15
A19: APPLIANCES | B19: Swamp Cooler | C19: 5 to 15 | D19: 10 | E19: 10 to 12
A20: APPLIANCES | B20: Washing Machine | C20: 5 to 15 | D20: 14 | E20: 11 | F20: 6 to 17
A21: DOORS | B21: Fiberglass (exterior) | C21: ='[1]Building Lifespan'!$B$2 -> 63 | D21: =$M$6 -> 63
A22: DOORS | B22: Fire-Rated Steel (exterior) | C22: 100+ | D22: =$M$6 -> 63
A23: DOORS | B23: Screen (exterior) | C23: 30 | D23: 30
A24: DOORS | B24: Sliding Glass/Patio (exterior) | C24: 20 | D24: 20
A25: DOORS | B25: Vinyl (exterior) | C25: 20 | D25: 20
A26: DOORS | B26: Wood (exterior) | C26: ='[1]Building Lifespan'!$B$2 -> 63 | D26: =$M$6 -> 63
A27: ELECTRICAL | B27: Fixtures | C27: 40 | D27: 40
A28: ELECTRICAL | B28: Lighting Controls | C28: 35 | D28: 35
A29: ELECTRICAL | B29: Residential Propane Backup Generators | C29: 12 | D29: 12
A30: ELECTRICAL | B30: Solar Panels | C30: 25 | D30: 25
A31: ELECTRICAL | B31: Solar System Batteries | C31: 3 to 12 | D31: 9 | E31: 7 to 10 | F31: 5 to 15
A32: ELECTRICAL | B32: Wind Turbine Generators | C32: 20 | D32: 20
A33: HVAC | B33: Air Conditioner (central) | C33: 7 to 15 | D33: 14 | E33: 15 to 20 | F33: 6 to 13 | G33: 21
A34: HVAC | B34: Air Exchanger | C34: 15 | D34: 15
A35: HVAC | B35: ASHP | C35: 15 | D35: 15 | E35: SOURCE
A36: HVAC | B36: Attic Fan | C36: 20 | D36: 20
A37: HVAC | B37: Boiler | C37: 40 | D37: 40
A38: HVAC | B38: Boiler- Electric | C38: 15 | D38: 15
A39: HVAC | B39: Boiler- Gas or oil | C39: 40 | D39: 33 | E39: 25 to 30
A40: HVAC | B40: Burner | C40: 10+ | D40: 10
...

Sheet In-House Pricing
A1: BUILDING SHELL MEASURES | L1: MECHANICAL MEASURES | W1: ELECTRICAL MEASURES | AH1: RENEWABLE ENERGY MEASURES
B3: EEM | C3: B1 | D3: =#REF! -> #REF! | M3: EEM | N3: M1 | O3: =#REF! -> #REF! | X3: EEM | Y3: E1 | Z3: =#REF! -> #REF! | AI3: EEM | AJ3: R1 | AK3: =#REF! -> #REF!
A4: ITEMS REQ. | B4: DIV. | C4: SECT. | D4: PG.# | F4: QTY. | G4: UNIT | H4: MAT. | I4: LABOR | J4: TOTAL | L4: ITEMS REQ. | M4: DIV. | N4: SECT. | O4: PG.# | Q4: QTY. | R4: UNIT | S4: MAT. | T4: LABOR | U4: TOTAL | W4: ITEMS REQ. | X4: DIV. | Y4: SECT. | Z4: PG.# | AB4: QTY. | AC4: UNIT | AD4: MAT. | AE4: LABOR | AF4: TOTAL | AH4: ITEMS REQ. | AI4: DIV. | AJ4: SECT. | AK4: PG.# | AM4: QTY. | AN4: UNIT | AO4: MAT. | AP4: LABOR | AQ4: TOTAL
A5: Remove ceiling tile at perimeter of retail store | B5: 9 | C5: 1200 | D5: 288 | F5: 1800 | G5: sf | I5: 0.35 | J5: =F5*(H5+I5) -> 630 | L5: Remove appropriate ceiling tiles | M5: 9 | N5: 1200 | O5: 288 | Q5: 80 | R5: sf | T5: 0.35 | U5: =Q5*(S5+T5) -> 28 | AF5: =AB5*(AD5+AE5) -> 0 | AQ5: =AM5*(AO5+AP5) -> 0
A6: Surgically air seal at roof to wall connection | F6: 1 | G6: LS | H6: 2800 | I6: 2200 | J6: =F6*(H6+I6) -> 5000 | L6: Demo existing duct runs (35"-0" each) | M6: 15 | N6: 1200 | O6: 482 | Q6: =(4+4)*20 -> 160 | R6: lf | T6: 2.12 | U6: =Q6*(S6+T6) -> 339.2 | AF6: =AB6*(AD6+AE6) -> 0 | AQ6: =AM6*(AO6+AP6) -> 0
A7: Replace ceiling tile at perimeter | B7: 9 | C7: 1200 | D7: 288 | F7: 1800 | G7: sf | I7: 0.35 | J7: =F7*(H7+I7) -> 630 | L7: Install duct runs (35"-0" each) | M7: 15 | N7: 1660 | O7: 493 | Q7: =(3*4)*20 -> 240 | R7: lf | S7: 3.17 | T7: 5.9 | U7: =Q7*(S7+T7) -> 2176.8 | AF7: =AB7*(AD7+AE7) -> 0 | AQ7: =AM7*(AO7+AP7) -> 0
J8: =F8*(H8+I8) -> 0 | L8: Install diffusers (24"x24") | M8: 15 | N8: 5280 | O8: 499 | Q8: =3*4 -> 12 | R8: ea | S8: 92 | T8: 35.5 | U8: =Q8*(S8+T8) -> 1530 | AF8: =AB8*(AD8+AE8) -> 0 | AQ8: =AM8*(AO8+AP8) -> 0
J9: =F9*(H9+I9) -> 0 | L9: Reinstall appropriate ceiling tiles | M9: 9 | N9: 1200 | O9: 288 | Q9: 80 | R9: sf | T9: 0.35 | U9: =Q9*(S9+T9) -> 28 | AF9: =AB9*(AD9+AE9) -> 0 | AQ9: =AM9*(AO9+AP9) -> 0
J10: =F10*(H10+I10) -> 0 | U10: =Q10*(S10+T10) -> 0 | AF10: =AB10*(AD10+AE10) -> 0 | AQ10: =AM10*(AO10+AP10) -> 0
J11: =F11*(H11+I11) -> 0 | U11: =Q11*(S11+T11) -> 0 | AF11: =AB11*(AD11+AE11) -> 0 | AQ11: =AM11*(AO11+AP11) -> 0
J12: =F12*(H12+I12) -> 0 | U12: =Q12*(S12+T12) -> 0 | AF12: =AB12*(AD12+AE12) -> 0 | AQ12: =AM12*(AO12+AP12) -> 0
I13: TOTAL | J13: =SUM(J5:J12) -> 6260 | T13: TOTAL | U13: =SUM(U5:U12) -> 4102 | AE13: TOTAL | AF13: =SUM(AF5:AF12) -> 0 | AP13: TOTAL | AQ13: =SUM(AQ5:AQ12) -> 0
B15: EEM | C15: B2 | D15: =#REF! -> #REF! | M15: EEM | N15: M2 | O15: =#REF! -> #REF! | X15: EEM | Y15: E2 | Z15: =#REF! -> #REF! | AI15: EEM | AJ15: E2 | AK15: =#REF! -> #REF!
A16: ITEMS REQ. | B16: DIV. | C16: SECT. | D16: PG.# | F16: QTY. | G16: UNIT | H16: MAT. | I16: LABOR | J16: TOTAL | L16: ITEMS REQ. | M16: DIV. | N16: SECT. | O16: PG.# | Q16: QTY. | R16: UNIT | S16: MAT. | T16: LABOR | U16: TOTAL | W16: ITEMS REQ. | X16: DIV. | Y16: SECT. | Z16: PG.# | AB16: QTY. | AC16: UNIT | AD16: MAT. | AE16: LABOR | AF16: TOTAL | AH16: ITEMS REQ. | AI16: DIV. | AJ16: SECT. | AK16: PG.# | AM16: QTY. | AN16: UNIT | AO16: MAT. | AP16: LABOR | AQ16: TOTAL
A17: Clean 10" diameter area around RTU | F17: 785.4 | G17: sf | I17: 0.86 | J17: =F17*(H17+I17) -> 675.444 | L17: Remove appropriate ceiling tiles | M17: 9 | N17: 1200 | O17: 288 | Q17: 40 | R17: sf | T17: 0.35 | U17: =Q17*(S17+T17) -> 14 | AF17: =AB17*(AD17+AE17) -> 0 | AQ17: =AM17*(AO17+AP17) -> 0
A18: Paint 10' diameter w/ cool roof coating | F18: =(3.1416*25)*10 -> 785.4 | G18: sf | H18: 7.5 | I18: 0.86 | J18: =F18*(H18+I18) -> 6565.944 | L18: Install duct runs (35"-0" each) | M18: 15 | N18: 1660 | O18: 493 | Q18: =35*4 -> 140 | R18: lf | S18: 3.17 | T18: 5.9 | U18: =Q18*(S18+T18) -> 1269.8 | AF18: =AB18*(AD18+AE18) -> 0 | AQ18: =AM18*(AO18+AP18) -> 0
J19: =F19*(H19+I19) -> 0 | L19: Install diffusers (24"x24") | M19: 15 | N19: 5280 | O19: 499 | Q19: =3*4 -> 12 | R19: ea | S19: 92 | T19: 35.5 | U19: =Q19*(S19+T19) -> 1530 | AF19: =AB19*(AD19+AE19) -> 0 | AQ19: =AM19*(AO19+AP19) -> 0
J20: =F20*(H20+I20) -> 0 | L20: Reinstall appropriate ceiling tiles | M20: 9 | N20: 1200 | O20: 288 | Q20: 40 | R20: sf | T20: 0.35 | U20: =Q20*(S20+T20) -> 14 | AF20: =AB20*(AD20+AE20) -> 0 | AQ20: =AM20*(AO20+AP20) -> 0
J21: =F21*(H21+I21) -> 0 | L21: Install fans | M21: 15 | N21: 7560 | O21: 495 | Q21: 4 | R21: ea | S21: 1125 | T21: 188 | U21: =Q21*(S21+T21) -> 5252 | AF21: =AB21*(AD21+AE21) -> 0 | AQ21: =AM21*(AO21+AP21) -> 0
J22: =F22*(H22+I22) -> 0 | L22: Install dampers | M22: 15 | N22: 6020 | O22: 492 | Q22: 4 | R22: ea | S22: 36.5 | T22: 22 | U22: =Q22*(S22+T22) -> 234 | AF22: =AB22*(AD22+AE22) -> 0 | AQ22: =AM22*(AO22+AP22) -> 0
J23: =F23*(H23+I23) -> 0 | L23: Install louvers | M23: 15 | N23: 3200 | O23: 499 | Q23: 4 | R23: ea | S23: 41.5 | T23: 14.05 | U23: =Q23*(S23+T23) -> 222.2 | AF23: =AB23*(AD23+AE23) -> 0 | AQ23: =AM23*(AO23+AP23) -> 0
J24: =F24*(H24+I24) -> 0 | U24: =Q24*(S24+T24) -> 0 | AF24: =AB24*(AD24+AE24) -> 0 | AQ24: =AM24*(AO24+AP24) -> 0
I25: TOTAL | J25: =SUM(J17:J24) -> 7241.388 | T25: TOTAL | U25: =SUM(U17:U24) -> 8536 | AE25: TOTAL | AF25: =SUM(AF17:AF24) -> 0 | AP25: TOTAL | AQ25: =SUM(AQ17:AQ24) -> 0
B27: EEM | C27: B3 | D27: =#REF! -> #REF! | M27: EEM | N27: M3 | O27: =#REF! -> #REF! | X27: EEM | Y27: E3 | Z27: =#REF! -> #REF! | AI27: EEM | AJ27: E3 | AK27: =#REF! -> #REF!
A28: ITEMS REQ. | B28: DIV. | C28: SECT. | D28: PG.# | F28: QTY. | G28: UNIT | H28: MAT. | I28: LABOR | J28: TOTAL | L28: ITEMS REQ. | M28: DIV. | N28: SECT. | O28: PG.# | Q28: QTY. | R28: UNIT | S28: MAT. | T28: LABOR | U28: TOTAL | W28: ITEMS REQ. | X28: DIV. | Y28: SECT. | Z28: PG.# | AB28: QTY. | AC28: UNIT | AD28: MAT. | AE28: LABOR | AF28: TOTAL | AH28: ITEMS REQ. | AI28: DIV. | AJ28: SECT. | AK28: PG.# | AM28: QTY. | AN28: UNIT | AO28: MAT. | AP28: LABOR | AQ28: TOTAL
J29: =F29*(H29+I29) -> 0 | U29: =Q29*(S29+T29) -> 0 | AF29: =AB29*(AD29+AE29) -> 0 | AQ29: =AM29*(AO29+AP29) -> 0
J30: =F30*(H30+I30) -> 0 | U30: =Q30*(S30+T30) -> 0 | AF30: =AB30*(AD30+AE30) -> 0 | AQ30: =AM30*(AO30+AP30) -> 0
J31: =F31*(H31+I31) -> 0 | U31: =Q31*(S31+T31) -> 0 | AF31: =AB31*(AD31+AE31) -> 0 | AQ31: =AM31*(AO31+AP31) -> 0
J32: =F32*(H32+I32) -> 0 | U32: =Q32*(S32+T32) -> 0 | AF32: =AB32*(AD32+AE32) -> 0 | AQ32: =AM32*(AO32+AP32) -> 0
J33: =F33*(H33+I33) -> 0 | U33: =Q33*(S33+T33) -> 0 | AF33: =AB33*(AD33+AE33) -> 0 | AQ33: =AM33*(AO33+AP33) -> 0
J34: =F34*(H34+I34) -> 0 | U34: =Q34*(S34+T34) -> 0 | AF34: =AB34*(AD34+AE34) -> 0 | AQ34: =AM34*(AO34+AP34) -> 0
J35: =F35*(H35+I35) -> 0 | U35: =Q35*(S35+T35) -> 0 | AF35: =AB35*(AD35+AE35) -> 0 | AQ35: =AM35*(AO35+AP35) -> 0
J36: =F36*(H36+I36) -> 0 | U36: =Q36*(S36+T36) -> 0 | AF36: =AB36*(AD36+AE36) -> 0 | AQ36: =AM36*(AO36+AP36) -> 0
I37: TOTAL | J37: =SUM(J29:J36) -> 0 | T37: TOTAL | U37: =SUM(U29:U36) -> 0 | AE37: TOTAL | AF37: =SUM(AF29:AF36) -> 0 | AP37: TOTAL | AQ37: =SUM(AQ29:AQ36) -> 0
B39: EEM | C39: B4 | D39: =#REF! -> #REF! | M39: EEM | N39: M4 | O39: =#REF! -> #REF! | X39: EEM | Y39: E4 | Z39: =#REF! -> #REF! | AI39: EEM | AJ39: E4 | AK39: =#REF! -> #REF!
A40: ITEMS REQ. | B40: DIV. | C40: SECT. | D40: PG.# | F40: QTY. | G40: UNIT | H40: MAT. | I40: LABOR | J40: TOTAL | L40: ITEMS REQ. | M40: DIV. | N40: SECT. | O40: PG.# | Q40: QTY. | R40: UNIT | S40: MAT. | T40: LABOR | U40: TOTAL | W40: ITEMS REQ. | X40: DIV. | Y40: SECT. | Z40: PG.# | AB40: QTY. | AC40: UNIT | AD40: MAT. | AE40: LABOR | AF40: TOTAL | AH40: ITEMS REQ. | AI40: DIV. | AJ40: SECT. | AK40: PG.# | AM40: QTY. | AN40: UNIT | AO40: MAT. | AP40: LABOR | AQ40: TOTAL
J41: =F41*(H41+I41) -> 0 | U41: =Q41*(S41+T41) -> 0 | AF41: =AB41*(AD41+AE41) -> 0 | AQ41: =AM41*(AO41+AP41) -> 0
J42: =F42*(H42+I42) -> 0 | U42: =Q42*(S42+T42) -> 0 | AF42: =AB42*(AD42+AE42) -> 0 | AQ42: =AM42*(AO42+AP42) -> 0
J43: =F43*(H43+I43) -> 0 | U43: =Q43*(S43+T43) -> 0 | AF43: =AB43*(AD43+AE43) -> 0 | AQ43: =AM43*(AO43+AP43) -> 0
J44: =F44*(H44+I44) -> 0 | U44: =Q44*(S44+T44) -> 0 | AF44: =AB44*(AD44+AE44) -> 0 | AQ44: =AM44*(AO44+AP44) -> 0
...

Sheet Interest Rate
A1: INTEREST RATE CALCULATOR
A3: STEP 1) FILL OUT THIS CALCULATOR | C3: NIST Energy Escalation Rate Calculator
A4: USING THE INFO IN THIS TABLE
A5: TO GET THE NOMINAL ESCALATION RATE | B5: Percent of Energy Cost Savings
B7: Coal | C7: Distillate Oil | D7: Electricity | E7: Natural Gas | F7: Residual
B8: 0 | C8: ='EEM Data Entry'!I160 -> #DIV/0! | D8: ='EEM Data Entry'!H160 -> #DIV/0! | E8: ='EEM Data Entry'!J160 -> #DIV/0! | F8: =1-(SUM(C8:E8)) -> #DIV/0!
B10: Inflation | C10: 0.034
A12: STEP 2) ENTER THE NOMINAL ESCALATION RATE HERE
A14: STEP 3) EDIT THE DISCOUNT RATE IF NEED (SHOULDN'T BE NECESSARY) | C14: 0.05
A15: Discount rate resource if needed
A17: INTEREST RATE CALCULATED = | B17: =((1+C14)/(1+C12))-1 -> 0.05

Sheet RESULTS
C1: COPY AND PASTE TABLES BELOW INTO REPORT AS APPROPRIATE, DELETE IRRELEVANT COLUMNS | V1: NO INCENTIVES
C3: ENVELOPE | I3: conversions | J3: 0.29307103 | K3: 0.0072790267 | L3: 0.01 | M3: 0.010928961 | V3: ENVELOPE | Y3: conversions | Z3: 0.29307103 | AA3: 0.0072790267 | AB3: 0.01 | AC3: 0.010928961
C5: EEM # | D5: Building Envelope Upgrades | E5: Capital Investment | F5: Estimated Incentive* | G5: Incentive Reference | H5: Estimated Net Cost | I5: Annual Energy Cost Savings | J5: Annual Electric Savings (kWh) | K5: Annual Oil Savings (Gal) | L5: Annual Nat. Gas Savings (Therms) | M5: Annual Propane Savings (Gal) | N5: Annual kBTU Savings | O5: Simple Payback (Years) | P5: IRR | Q5: NPV | V5: =C5 -> EEM # | W5: =D5 -> Building Envelope Upgrades | X5: =E5 -> Capital Investment | Y5: =I5 -> Annual Energy Cost Savings | Z5: =J5 -> Annual Electric Savings (kWh) | AA5: =K5 -> Annual Oil Savings (Gal) | AB5: =L5 -> Annual Nat. Gas Savings (Therms) | AC5: =M5 -> Annual Propane Savings (Gal) | AD5: =O5 -> Simple Payback (Years) | AE5: =P5 -> IRR | AF5: =Q5 -> NPV | AQ5: Annual kBTU Savings
A6: =SUM(B6) -> 1 | B6: =IF(ISTEXT(D6)=TRUE,1,0) -> 1 | C6: ='Individual Measure List'!A8 | D6: ='Individual Measure List'!B8 | E6: ='EEM Data Entry'!D85 | F6: ='EEM Data Entry'!E85 | G6: ='EEM Data Entry'!G85 -> N/A | H6: ='EEM Data Entry'!F85 | I6: ='Individual Measure List'!F8 -> 0 | J6: =IF('Savings Summary'!D7=0,"",'Savings Summary'!D7) | K6: =IF('Savings Summary'!F7=0,"",'Savings Summary'!F7) | L6: =IF('Savings Summary'!H7=0,"",'Savings Summary'!H7) | M6: =IF('Savings Summary'!J7=0,"",'Savings Summary'!J7) | N6: =IF('RESULTS kBtu'!H6=0,"",'RESULTS kBtu'!H6) | O6: ='Individual Measure List'!H8 -> #VALUE! | P6: ='Individual Measure List'!J8 -> #NUM! | Q6: ='Individual Measure List'!K8 -> #VALUE! | S6: Discount Rate Assumptions | V6: =C6 | W6: =D6 | X6: =E6 | Y6: =I6 -> 0 | Z6: =J6 | AA6: =K6 | AB6: =L6 | AC6: =M6 | AD6: =O6 -> #VALUE! | AE6: =P6 -> #NUM! | AF6: =Q6 -> #VALUE! | AQ6: ='Individual Measure List'!G8 -> 0
A7: =SUM(B6:B7) -> 2 | B7: =IF(ISTEXT(D7)=TRUE,1,0) -> 1 | C7: ='Individual Measure List'!A9 | D7: ='Individual Measure List'!B9 | E7: ='EEM Data Entry'!D86 | F7: ='EEM Data Entry'!E86 | G7: ='EEM Data Entry'!G86 -> N/A | H7: ='EEM Data Entry'!F86 | I7: ='Individual Measure List'!F9 -> 0 | J7: =IF('Savings Summary'!D8=0,"",'Savings Summary'!D8) | K7: =IF('Savings Summary'!F8=0,"",'Savings Summary'!F8) | L7: =IF('Savings Summary'!H8=0,"",'Savings Summary'!H8) | M7: =IF('Savings Summary'!J8=0,"",'Savings Summary'!J8) | N7: =IF('RESULTS kBtu'!H7=0,"",'RESULTS kBtu'!H7) | O7: ='Individual Measure List'!H9 -> #VALUE! | P7: ='Individual Measure List'!J9 -> #NUM! | Q7: ='Individual Measure List'!K9 -> #VALUE! | S7: Inflation | T7: ='Interest Rate'!C10 -> 0.034 | V7: =C7 | W7: =D7 | X7: =E7 | Y7: =I7 -> 0 | Z7: =J7 | AA7: =K7 | AB7: =L7 | AC7: =M7 | AD7: =O7 -> #VALUE! | AE7: =P7 -> #NUM! | AF7: =Q7 -> #VALUE! | AQ7: ='Individual Measure List'!G9 -> 0
A8: =SUM(B6:B8) -> 3 | B8: =IF(ISTEXT(D8)=TRUE,1,0) -> 1 | C8: ='Individual Measure List'!A10 | D8: ='Individual Measure List'!B10 | E8: ='EEM Data Entry'!D87 | F8: ='EEM Data Entry'!E87 | G8: ='EEM Data Entry'!G87 -> N/A | H8: ='EEM Data Entry'!F87 | I8: ='Individual Measure List'!F10 -> 0 | J8: =IF('Savings Summary'!D9=0,"",'Savings Summary'!D9) | K8: =IF('Savings Summary'!F9=0,"",'Savings Summary'!F9) | L8: =IF('Savings Summary'!H9=0,"",'Savings Summary'!H9) | M8: =IF('Savings Summary'!J9=0,"",'Savings Summary'!J9) | N8: =IF('RESULTS kBtu'!H8=0,"",'RESULTS kBtu'!H8) | O8: ='Individual Measure List'!H10 -> #VALUE! | P8: ='Individual Measure List'!J10 -> #NUM! | Q8: ='Individual Measure List'!K10 -> #VALUE! | S8: Nominal Escalation Rate | T8: ='Interest Rate'!C12 -> 0 | V8: =C8 | W8: =D8 | X8: =E8 | Y8: =I8 -> 0 | Z8: =J8 | AA8: =K8 | AB8: =L8 | AC8: =M8 | AD8: =O8 -> #VALUE! | AE8: =P8 -> #NUM! | AF8: =Q8 -> #VALUE! | AQ8: ='Individual Measure List'!G10 -> 0
A9: =SUM(B6:B9) -> 4 | B9: =IF(ISTEXT(D9)=TRUE,1,0) -> 1 | C9: ='Individual Measure List'!A11 | D9: ='Individual Measure List'!B11 | E9: ='EEM Data Entry'!D88 | F9: ='EEM Data Entry'!E88 | G9: ='EEM Data Entry'!G88 -> N/A | H9: ='EEM Data Entry'!F88 | I9: ='Individual Measure List'!F11 -> 0 | J9: =IF('Savings Summary'!D10=0,"",'Savings Summary'!D10) | K9: =IF('Savings Summary'!F10=0,"",'Savings Summary'!F10) | L9: =IF('Savings Summary'!H10=0,"",'Savings Summary'!H10) | M9: =IF('Savings Summary'!J10=0,"",'Savings Summary'!J10) | N9: =IF('RESULTS kBtu'!H9=0,"",'RESULTS kBtu'!H9) | O9: ='Individual Measure List'!H11 -> #VALUE! | P9: ='Individual Measure List'!J11 -> #NUM! | Q9: ='Individual Measure List'!K11 -> #VALUE! | S9: Discount Rate | T9: ='Interest Rate'!C14 -> 0.05 | V9: =C9 | W9: =D9 | X9: =E9 | Y9: =I9 -> 0 | Z9: =J9 | AA9: =K9 | AB9: =L9 | AC9: =M9 | AD9: =O9 -> #VALUE! | AE9: =P9 -> #NUM! | AF9: =Q9 -> #VALUE! | AQ9: ='Individual Measure List'!G11 -> 0
A10: =SUM(B6:B10) -> 5 | B10: =IF(ISTEXT(D10)=TRUE,1,0) -> 1 | C10: ='Individual Measure List'!A12 | D10: ='Individual Measure List'!B12 | E10: ='EEM Data Entry'!D89 | F10: ='EEM Data Entry'!E89 | G10: ='EEM Data Entry'!G89 -> N/A | H10: ='EEM Data Entry'!F89 | I10: ='Individual Measure List'!F12 -> 0 | J10: =IF('Savings Summary'!D11=0,"",'Savings Summary'!D11) | K10: =IF('Savings Summary'!F11=0,"",'Savings Summary'!F11) | L10: =IF('Savings Summary'!H11=0,"",'Savings Summary'!H11) | M10: =IF('Savings Summary'!J11=0,"",'Savings Summary'!J11) | N10: =IF('RESULTS kBtu'!H10=0,"",'RESULTS kBtu'!H10) | O10: ='Individual Measure List'!H12 -> #VALUE! | P10: ='Individual Measure List'!J12 -> #NUM! | Q10: ='Individual Measure List'!K12 -> #VALUE! | S10: Adjusted Discount Rate | T10: ='Interest Rate'!B17 -> 0.05 | V10: =C10 | W10: =D10 | X10: =E10 | Y10: =I10 -> 0 | Z10: =J10 | AA10: =K10 | AB10: =L10 | AC10: =M10 | AD10: =O10 -> #VALUE! | AE10: =P10 -> #NUM! | AF10: =Q10 -> #VALUE! | AQ10: ='Individual Measure List'!G12 -> 0
A11: =SUM(B6:B11) -> 6 | B11: =IF(ISTEXT(D11)=TRUE,1,0) -> 1 | C11: ='Individual Measure List'!A13 | D11: ='Individual Measure List'!B13 | E11: ='EEM Data Entry'!D90 | F11: ='EEM Data Entry'!E90 | G11: ='EEM Data Entry'!G90 -> N/A | H11: ='EEM Data Entry'!F90 | I11: ='Individual Measure List'!F13 -> 0 | J11: =IF('Savings Summary'!D12=0,"",'Savings Summary'!D12) | K11: =IF('Savings Summary'!F12=0,"",'Savings Summary'!F12) | L11: =IF('Savings Summary'!H12=0,"",'Savings Summary'!H12) | M11: =IF('Savings Summary'!J12=0,"",'Savings Summary'!J12) | N11: =IF('RESULTS kBtu'!H11=0,"",'RESULTS kBtu'!H11) | O11: ='Individual Measure List'!H13 -> #VALUE! | P11: ='Individual Measure List'!J13 -> #NUM! | Q11: ='Individual Measure List'!K13 -> #VALUE! | S11: *Calculated using the Nation Institute of Standards and Technology (NIST) Energy Escalation Rate Calculator | V11: =C11 | W11: =D11 | X11: =E11 | Y11: =I11 -> 0 | Z11: =J11 | AA11: =K11 | AB11: =L11 | AC11: =M11 | AD11: =O11 -> #VALUE! | AE11: =P11 -> #NUM! | AF11: =Q11 -> #VALUE! | AQ11: ='Individual Measure List'!G13 -> 0
A12: =SUM(B6:B12) -> 7 | B12: =IF(ISTEXT(D12)=TRUE,1,0) -> 1 | C12: ='Individual Measure List'!A14 | D12: ='Individual Measure List'!B14 | E12: ='EEM Data Entry'!D91 | F12: ='EEM Data Entry'!E91 | G12: ='EEM Data Entry'!G91 -> N/A | H12: ='EEM Data Entry'!F91 | I12: ='Individual Measure List'!F14 -> 0 | J12: =IF('Savings Summary'!D13=0,"",'Savings Summary'!D13) | K12: =IF('Savings Summary'!F13=0,"",'Savings Summary'!F13) | L12: =IF('Savings Summary'!H13=0,"",'Savings Summary'!H13) | M12: =IF('Savings Summary'!J13=0,"",'Savings Summary'!J13) | N12: =IF('RESULTS kBtu'!H12=0,"",'RESULTS kBtu'!H12) | O12: ='Individual Measure List'!H14 -> #VALUE! | P12: ='Individual Measure List'!J14 -> #NUM! | Q12: ='Individual Measure List'!K14 -> #VALUE! | V12: =C12 | W12: =D12 | X12: =E12 | Y12: =I12 -> 0 | Z12: =J12 | AA12: =K12 | AB12: =L12 | AC12: =M12 | AD12: =O12 -> #VALUE! | AE12: =P12 -> #NUM! | AF12: =Q12 -> #VALUE! | AQ12: ='Individual Measure List'!G14 -> 0
A13: =SUM(B6:B13) -> 8 | B13: =IF(ISTEXT(D13)=TRUE,1,0) -> 1 | C13: ='Individual Measure List'!A15 | D13: ='Individual Measure List'!B15 | E13: ='EEM Data Entry'!D92 | F13: ='EEM Data Entry'!E92 | G13: ='EEM Data Entry'!G92 -> N/A | H13: ='EEM Data Entry'!F92 | I13: ='Individual Measure List'!F15 -> 0 | J13: =IF('Savings Summary'!D14=0,"",'Savings Summary'!D14) | K13: =IF('Savings Summary'!F14=0,"",'Savings Summary'!F14) | L13: =IF('Savings Summary'!H14=0,"",'Savings Summary'!H14) | M13: =IF('Savings Summary'!J14=0,"",'Savings Summary'!J14) | N13: =IF('RESULTS kBtu'!H13=0,"",'RESULTS kBtu'!H13) | O13: ='Individual Measure List'!H15 -> #VALUE! | P13: ='Individual Measure List'!J15 -> #NUM! | Q13: ='Individual Measure List'!K15 -> #VALUE! | V13: =C13 | W13: =D13 | X13: =E13 | Y13: =I13 -> 0 | Z13: =J13 | AA13: =K13 | AB13: =L13 | AC13: =M13 | AD13: =O13 -> #VALUE! | AE13: =P13 -> #NUM! | AF13: =Q13 -> #VALUE! | AQ13: ='Individual Measure List'!G15 -> 0
A14: =SUM(B6:B14) -> 9 | B14: =IF(ISTEXT(D14)=TRUE,1,0) -> 1 | C14: ='Individual Measure List'!A16 | D14: ='Individual Measure List'!B16 | E14: ='EEM Data Entry'!D93 | F14: ='EEM Data Entry'!E93 | G14: ='EEM Data Entry'!G93 -> N/A | H14: ='EEM Data Entry'!F93 | I14: ='Individual Measure List'!F16 -> 0 | J14: =IF('Savings Summary'!D15=0,"",'Savings Summary'!D15) | K14: =IF('Savings Summary'!F15=0,"",'Savings Summary'!F15) | L14: =IF('Savings Summary'!H15=0,"",'Savings Summary'!H15) | M14: =IF('Savings Summary'!J15=0,"",'Savings Summary'!J15) | N14: =IF('RESULTS kBtu'!H14=0,"",'RESULTS kBtu'!H14) | O14: ='Individual Measure List'!H16 -> #VALUE! | P14: ='Individual Measure List'!J16 -> #NUM! | Q14: ='Individual Measure List'!K16 -> #VALUE! | V14: =C14 | W14: =D14 | X14: =E14 | Y14: =I14 -> 0 | Z14: =J14 | AA14: =K14 | AB14: =L14 | AC14: =M14 | AD14: =O14 -> #VALUE! | AE14: =P14 -> #NUM! | AF14: =Q14 -> #VALUE! | AQ14: ='Individual Measure List'!G16 -> 0
A15: =SUM(B6:B15) -> 10 | B15: =IF(ISTEXT(D15)=TRUE,1,0) -> 1 | C15: ='Individual Measure List'!A17 | D15: ='Individual Measure List'!B17 | E15: ='EEM Data Entry'!D94 | F15: ='EEM Data Entry'!E94 | G15: ='EEM Data Entry'!G94 -> N/A | H15: ='EEM Data Entry'!F94 | I15: ='Individual Measure List'!F17 -> 0 | J15: =IF('Savings Summary'!D16=0,"",'Savings Summary'!D16) | K15: =IF('Savings Summary'!F16=0,"",'Savings Summary'!F16) | L15: =IF('Savings Summary'!H16=0,"",'Savings Summary'!H16) | M15: =IF('Savings Summary'!J16=0,"",'Savings Summary'!J16) | N15: =IF('RESULTS kBtu'!H15=0,"",'RESULTS kBtu'!H15) | O15: ='Individual Measure List'!H17 -> #VALUE! | P15: ='Individual Measure List'!J17 -> #NUM! | Q15: ='Individual Measure List'!K17 -> #VALUE! | V15: =C15 | W15: =D15 | X15: =E15 | Y15: =I15 -> 0 | Z15: =J15 | AA15: =K15 | AB15: =L15 | AC15: =M15 | AD15: =O15 -> #VALUE! | AE15: =P15 -> #NUM! | AF15: =Q15 -> #VALUE! | AQ15: ='Individual Measure List'!G17 -> 0
C16: *Please see "Note Regarding Incentives" on first page of financial modeling section | V16: *Please see "Note Regarding Incentives" on first page of financial modeling section
C18: MECHANICAL | V18: MECHANICAL
C20: EEM # | D20: Mechanical System Upgrades | E20: Capital Investment | F20: Estimated Incentive* | G20: Incentive Reference | H20: Estimated Net Cost | I20: Annual Energy Cost Savings | J20: Annual Electric Savings (kWh) | K20: Annual Oil Savings (Gal) | L20: Annual Nat. Gas Savings (Therms) | M20: Annual Propane Savings (Gal) | N20: Annual kBTU Savings | O20: Simple Payback (Years) | P20: IRR | Q20: NPV | V20: =C20 -> EEM # | W20: =D20 -> Mechanical System Upgrades | X20: =E20 -> Capital Investment | Y20: =I20 -> Annual Energy Cost Savings | Z20: =J20 -> Annual Electric Savings (kWh) | AA20: =K20 -> Annual Oil Savings (Gal) | AB20: =L20 -> Annual Nat. Gas Savings (Therms) | AC20: =M20 -> Annual Propane Savings (Gal) | AD20: =O20 -> Simple Payback (Years) | AE20: =P20 -> IRR | AF20: =Q20 -> NPV | AQ20: Annual kBTU Savings
A21: =SUM(B6:B21) -> 11 | B21: =IF(ISTEXT(D21)=TRUE,1,0) -> 1 | C21: ='Individual Measure List'!A33 | D21: ='Individual Measure List'!B33 | E21: ='EEM Data Entry'!D110 | F21: ='EEM Data Entry'!E110 | G21: ='EEM Data Entry'!G110 -> N/A | H21: ='EEM Data Entry'!F110 | I21: ='Individual Measure List'!F33 -> 0 | J21: =IF('Savings Summary'!D34=0,"",'Savings Summary'!D34) | K21: =IF('Savings Summary'!F34=0,"",'Savings Summary'!F34) | L21: =IF('Savings Summary'!H34=0,"",'Savings Summary'!H34) | M21: =IF('Savings Summary'!J34=0,"",'Savings Summary'!J34) | N21: =IF('RESULTS kBtu'!H21=0,"",'RESULTS kBtu'!H21) | O21: ='Individual Measure List'!H33 -> #VALUE! | P21: ='Individual Measure List'!J33 -> #NUM! | Q21: ='Individual Measure List'!K33 -> #VALUE! | V21: =C21 | W21: =D21 | X21: =E21 | Y21: =I21 -> 0 | Z21: =J21 | AA21: =K21 | AB21: =L21 | AC21: =M21 | AD21: =O21 -> #VALUE! | AE21: =P21 -> #NUM! | AF21: =Q21 -> #VALUE! | AQ21: ='Individual Measure List'!G33 -> 0
A22: =SUM(B6:B22) -> 12 | B22: =IF(ISTEXT(D22)=TRUE,1,0) -> 1 | C22: ='Individual Measure List'!A34 | D22: ='Individual Measure List'!B34 | E22: ='EEM Data Entry'!D111 | F22: ='EEM Data Entry'!E111 | G22: ='EEM Data Entry'!G111 -> N/A | H22: ='EEM Data Entry'!F111 | I22: ='Individual Measure List'!F34 -> 0 | J22: =IF('Savings Summary'!D35=0,"",'Savings Summary'!D35) | K22: =IF('Savings Summary'!F35=0,"",'Savings Summary'!F35) | L22: =IF('Savings Summary'!H35=0,"",'Savings Summary'!H35) | M22: =IF('Savings Summary'!J35=0,"",'Savings Summary'!J35) | N22: =IF('RESULTS kBtu'!H22=0,"",'RESULTS kBtu'!H22) | O22: ='Individual Measure List'!H34 -> #VALUE! | P22: ='Individual Measure List'!J34 -> #NUM! | Q22: ='Individual Measure List'!K34 -> #VALUE! | V22: =C22 | W22: =D22 | X22: =E22 | Y22: =I22 -> 0 | Z22: =J22 | AA22: =K22 | AB22: =L22 | AC22: =M22 | AD22: =O22 -> #VALUE! | AE22: =P22 -> #NUM! | AF22: =Q22 -> #VALUE! | AQ22: ='Individual Measure List'!G34 -> 0
A23: =SUM(B6:B23) -> 13 | B23: =IF(ISTEXT(D23)=TRUE,1,0) -> 1 | C23: ='Individual Measure List'!A35 | D23: ='Individual Measure List'!B35 | E23: ='EEM Data Entry'!D112 | F23: ='EEM Data Entry'!E112 | G23: ='EEM Data Entry'!G112 -> N/A | H23: ='EEM Data Entry'!F112 | I23: ='Individual Measure List'!F35 -> 0 | J23: =IF('Savings Summary'!D36=0,"",'Savings Summary'!D36) | K23: =IF('Savings Summary'!F36=0,"",'Savings Summary'!F36) | L23: =IF('Savings Summary'!H36=0,"",'Savings Summary'!H36) | M23: =IF('Savings Summary'!J36=0,"",'Savings Summary'!J36) | N23: =IF('RESULTS kBtu'!H23=0,"",'RESULTS kBtu'!H23) | O23: ='Individual Measure List'!H35 -> #VALUE! | P23: ='Individual Measure List'!J35 -> #NUM! | Q23: ='Individual Measure List'!K35 -> #VALUE! | V23: =C23 | W23: =D23 | X23: =E23 | Y23: =I23 -> 0 | Z23: =J23 | AA23: =K23 | AB23: =L23 | AC23: =M23 | AD23: =O23 -> #VALUE! | AE23: =P23 -> #NUM! | AF23: =Q23 -> #VALUE! | AQ23: ='Individual Measure List'!G35 -> 0
A24: =SUM(B6:B24) -> 14 | B24: =IF(ISTEXT(D24)=TRUE,1,0) -> 1 | C24: ='Individual Measure List'!A36 | D24: ='Individual Measure List'!B36 | E24: ='EEM Data Entry'!D113 | F24: ='EEM Data Entry'!E113 | G24: ='EEM Data Entry'!G113 -> N/A | H24: ='EEM Data Entry'!F113 | I24: ='Individual Measure List'!F36 -> 0 | J24: =IF('Savings Summary'!D37=0,"",'Savings Summary'!D37) | K24: =IF('Savings Summary'!F37=0,"",'Savings Summary'!F37) | L24: =IF('Savings Summary'!H37=0,"",'Savings Summary'!H37) | M24: =IF('Savings Summary'!J37=0,"",'Savings Summary'!J37) | N24: =IF('RESULTS kBtu'!H24=0,"",'RESULTS kBtu'!H24) | O24: ='Individual Measure List'!H36 -> #VALUE! | P24: ='Individual Measure List'!J36 -> #NUM! | Q24: ='Individual Measure List'!K36 -> #VALUE! | V24: =C24 | W24: =D24 | X24: =E24 | Y24: =I24 -> 0 | Z24: =J24 | AA24: =K24 | AB24: =L24 | AC24: =M24 | AD24: =O24 -> #VALUE! | AE24: =P24 -> #NUM! | AF24: =Q24 -> #VALUE! | AQ24: ='Individual Measure List'!G36 -> 0
A25: =SUM(B6:B25) -> 15 | B25: =IF(ISTEXT(D25)=TRUE,1,0) -> 1 | C25: ='Individual Measure List'!A37 | D25: ='Individual Measure List'!B37 | E25: ='EEM Data Entry'!D114 | F25: ='EEM Data Entry'!E114 | G25: ='EEM Data Entry'!G114 -> N/A | H25: ='EEM Data Entry'!F114 | I25: ='Individual Measure List'!F37 -> 0 | J25: =IF('Savings Summary'!D38=0,"",'Savings Summary'!D38) | K25: =IF('Savings Summary'!F38=0,"",'Savings Summary'!F38) | L25: =IF('Savings Summary'!H38=0,"",'Savings Summary'!H38) | M25: =IF('Savings Summary'!J38=0,"",'Savings Summary'!J38) | N25: =IF('RESULTS kBtu'!H25=0,"",'RESULTS kBtu'!H25) | O25: ='Individual Measure List'!H37 -> #VALUE! | P25: ='Individual Measure List'!J37 -> #NUM! | Q25: ='Individual Measure List'!K37 -> #VALUE! | V25: =C25 | W25: =D25 | X25: =E25 | Y25: =I25 -> 0 | Z25: =J25 | AA25: =K25 | AB25: =L25 | AC25: =M25 | AD25: =O25 -> #VALUE! | AE25: =P25 -> #NUM! | AF25: =Q25 -> #VALUE! | AQ25: ='Individual Measure List'!G37 -> 0
A26: =SUM(B6:B26) -> 16 | B26: =IF(ISTEXT(D26)=TRUE,1,0) -> 1 | C26: ='Individual Measure List'!A38 | D26: ='Individual Measure List'!B38 | E26: ='EEM Data Entry'!D115 | F26: ='EEM Data Entry'!E115 | G26: ='EEM Data Entry'!G115 -> N/A | H26: ='EEM Data Entry'!F115 | I26: ='Individual Measure List'!F38 -> 0 | J26: =IF('Savings Summary'!D39=0,"",'Savings Summary'!D39) | K26: =IF('Savings Summary'!F39=0,"",'Savings Summary'!F39) | L26: =IF('Savings Summary'!H39=0,"",'Savings Summary'!H39) | M26: =IF('Savings Summary'!J39=0,"",'Savings Summary'!J39) | N26: =IF('RESULTS kBtu'!H26=0,"",'RESULTS kBtu'!H26) | O26: ='Individual Measure List'!H38 -> #VALUE! | P26: ='Individual Measure List'!J38 -> #NUM! | Q26: ='Individual Measure List'!K38 -> #VALUE! | V26: =C26 | W26: =D26 | X26: =E26 | Y26: =I26 -> 0 | Z26: =J26 | AA26: =K26 | AB26: =L26 | AC26: =M26 | AD26: =O26 -> #VALUE! | AE26: =P26 -> #NUM! | AF26: =Q26 -> #VALUE! | AQ26: ='Individual Measure List'!G38 -> 0
A27: =SUM(B6:B27) -> 17 | B27: =IF(ISTEXT(D27)=TRUE,1,0) -> 1 | C27: ='Individual Measure List'!A39 | D27: ='Individual Measure List'!B39 | E27: ='EEM Data Entry'!D116 | F27: ='EEM Data Entry'!E116 | G27: ='EEM Data Entry'!G116 -> N/A | H27: ='EEM Data Entry'!F116 | I27: ='Individual Measure List'!F39 -> 0 | J27: =IF('Savings Summary'!D40=0,"",'Savings Summary'!D40) | K27: =IF('Savings Summary'!F40=0,"",'Savings Summary'!F40) | L27: =IF('Savings Summary'!H40=0,"",'Savings Summary'!H40) | M27: =IF('Savings Summary'!J40=0,"",'Savings Summary'!J40) | N27: =IF('RESULTS kBtu'!H27=0,"",'RESULTS kBtu'!H27) | O27: ='Individual Measure List'!H39 -> #VALUE! | P27: ='Individual Measure List'!J39 -> #NUM! | Q27: ='Individual Measure List'!K39 -> #VALUE! | V27: =C27 | W27: =D27 | X27: =E27 | Y27: =I27 -> 0 | Z27: =J27 | AA27: =K27 | AB27: =L27 | AC27: =M27 | AD27: =O27 -> #VALUE! | AE27: =P27 -> #NUM! | AF27: =Q27 -> #VALUE! | AQ27: ='Individual Measure List'!G39 -> 0
A28: =SUM(B6:B28) -> 18 | B28: =IF(ISTEXT(D28)=TRUE,1,0) -> 1 | C28: ='Individual Measure List'!A40 | D28: ='Individual Measure List'!B40 | E28: ='EEM Data Entry'!D117 | F28: ='EEM Data Entry'!E117 | G28: ='EEM Data Entry'!G117 -> N/A | H28: ='EEM Data Entry'!F117 | I28: ='Individual Measure List'!F40 -> 0 | J28: =IF('Savings Summary'!D41=0,"",'Savings Summary'!D41) | K28: =IF('Savings Summary'!F41=0,"",'Savings Summary'!F41) | L28: =IF('Savings Summary'!H41=0,"",'Savings Summary'!H41) | M28: =IF('Savings Summary'!J41=0,"",'Savings Summary'!J41) | N28: =IF('RESULTS kBtu'!H28=0,"",'RESULTS kBtu'!H28) | O28: ='Individual Measure List'!H40 -> #VALUE! | P28: ='Individual Measure List'!J40 -> #NUM! | Q28: ='Individual Measure List'!K40 -> #VALUE! | V28: =C28 | W28: =D28 | X28: =E28 | Y28: =I28 -> 0 | Z28: =J28 | AA28: =K28 | AB28: =L28 | AC28: =M28 | AD28: =O28 -> #VALUE! | AE28: =P28 -> #NUM! | AF28: =Q28 -> #VALUE! | AQ28: ='Individual Measure List'!G40 -> 0
A29: =SUM(B6:B29) -> 19 | B29: =IF(ISTEXT(D29)=TRUE,1,0) -> 1 | C29: ='Individual Measure List'!A41 | D29: ='Individual Measure List'!B41 | E29: ='EEM Data Entry'!D118 | F29: ='EEM Data Entry'!E118 | G29: ='EEM Data Entry'!G118 -> N/A | H29: ='EEM Data Entry'!F118 | I29: ='Individual Measure List'!F41 -> 0 | J29: =IF('Savings Summary'!D42=0,"",'Savings Summary'!D42) | K29: =IF('Savings Summary'!F42=0,"",'Savings Summary'!F42) | L29: =IF('Savings Summary'!H42=0,"",'Savings Summary'!H42) | M29: =IF('Savings Summary'!J42=0,"",'Savings Summary'!J42) | N29: =IF('RESULTS kBtu'!H29=0,"",'RESULTS kBtu'!H29) | O29: ='Individual Measure List'!H41 -> #VALUE! | P29: ='Individual Measure List'!J41 -> #NUM! | Q29: ='Individual Measure List'!K41 -> #VALUE! | V29: =C29 | W29: =D29 | X29: =E29 | Y29: =I29 -> 0 | Z29: =J29 | AA29: =K29 | AB29: =L29 | AC29: =M29 | AD29: =O29 -> #VALUE! | AE29: =P29 -> #NUM! | AF29: =Q29 -> #VALUE! | AQ29: ='Individual Measure List'!G41 -> 0
A30: =SUM(B6:B30) -> 20 | B30: =IF(ISTEXT(D30)=TRUE,1,0) -> 1 | C30: ='Individual Measure List'!A42 | D30: ='Individual Measure List'!B42 | E30: ='EEM Data Entry'!D119 | F30: ='EEM Data Entry'!E119 | G30: ='EEM Data Entry'!G119 -> N/A | H30: ='EEM Data Entry'!F119 | I30: ='Individual Measure List'!F42 -> 0 | J30: =IF('Savings Summary'!D43=0,"",'Savings Summary'!D43) | K30: =IF('Savings Summary'!F43=0,"",'Savings Summary'!F43) | L30: =IF('Savings Summary'!H43=0,"",'Savings Summary'!H43) | M30: =IF('Savings Summary'!J43=0,"",'Savings Summary'!J43) | N30: =IF('RESULTS kBtu'!H30=0,"",'RESULTS kBtu'!H30) | O30: ='Individual Measure List'!H42 -> #VALUE! | P30: ='Individual Measure List'!J42 -> #NUM! | Q30: ='Individual Measure List'!K42 -> #VALUE! | V30: =C30 | W30: =D30 | X30: =E30 | Y30: =I30 -> 0 | Z30: =J30 | AA30: =K30 | AB30: =L30 | AC30: =M30 | AD30: =O30 -> #VALUE! | AE30: =P30 -> #NUM! | AF30: =Q30 -> #VALUE! | AQ30: ='Individual Measure List'!G42 -> 0
C31: *Please see "Note Regarding Incentives" on first page of financial modeling section | V31: *Please see "Note Regarding Incentives" on first page of financial modeling section
C33: APPLIANCES & LIGHTING | V33: APPLIANCES & LIGHTING
C35: EEM # | D35: Appliances & Lighting Upgrades | E35: Capital Investment | F35: Estimated Incentive* | G35: Incentive Reference | H35: Estimated Net Cost | I35: Annual Energy Cost Savings | J35: Annual Electric Savings (kWh) | K35: Annual Oil Savings (Gal) | L35: Annual Nat. Gas Savings (Therms) | M35: Annual Propane Savings (Gal) | N35: Annual kBTU Savings | O35: Simple Payback (Years) | P35: IRR | Q35: NPV | V35: =C35 -> EEM # | W35: =D35 -> Appliances & Lighting Upgrades | X35: =E35 -> Capital Investment | Y35: =I35 -> Annual Energy Cost Savings | Z35: =J35 -> Annual Electric Savings (kWh) | AA35: =K35 -> Annual Oil Savings (Gal) | AB35: =L35 -> Annual Nat. Gas Savings (Therms) | AC35: =M35 -> Annual Propane Savings (Gal) | AD35: =O35 -> Simple Payback (Years) | AE35: =P35 -> IRR | AF35: =Q35 -> NPV | AQ35: Annual kBTU Savings
A36: =SUM(B6:B36) -> 21 | B36: =IF(ISTEXT(D36)=TRUE,1,0) -> 1 | C36: ='Individual Measure List'!A49 | D36: ='Individual Measure List'!B49 | E36: ='EEM Data Entry'!D125 | F36: ='EEM Data Entry'!E125 | G36: ='EEM Data Entry'!G125 -> N/A | H36: ='EEM Data Entry'!F125 | I36: ='Individual Measure List'!F49 -> 0 | J36: =IF('Savings Summary'!D51=0,"",'Savings Summary'!D51) | K36: =IF('Savings Summary'!F51=0,"",'Savings Summary'!F51) | L36: =IF('Savings Summary'!H51=0,"",'Savings Summary'!H51) | M36: =IF('Savings Summary'!J51=0,"",'Savings Summary'!J51) | N36: =IF('RESULTS kBtu'!H36=0,"",'RESULTS kBtu'!H36) | O36: ='Individual Measure List'!H49 -> #VALUE! | P36: ='Individual Measure List'!J49 -> #NUM! | Q36: ='Individual Measure List'!K49 -> #VALUE! | V36: =C36 | W36: =D36 | X36: =E36 | Y36: =I36 -> 0 | Z36: =J36 | AA36: =K36 | AB36: =L36 | AC36: =M36 | AD36: =O36 -> #VALUE! | AE36: =P36 -> #NUM! | AF36: =Q36 -> #VALUE! | AQ36: ='Individual Measure List'!G49 -> 0
A37: =SUM(B6:B37) -> 22 | B37: =IF(ISTEXT(D37)=TRUE,1,0) -> 1 | C37: ='Individual Measure List'!A50 | D37: ='Individual Measure List'!B50 | E37: ='EEM Data Entry'!D126 | F37: ='EEM Data Entry'!E126 | G37: ='EEM Data Entry'!G126 -> N/A | H37: ='EEM Data Entry'!F126 | I37: ='Individual Measure List'!F50 -> 0 | J37: =IF('Savings Summary'!D52=0,"",'Savings Summary'!D52) | K37: =IF('Savings Summary'!F52=0,"",'Savings Summary'!F52) | L37: =IF('Savings Summary'!H52=0,"",'Savings Summary'!H52) | M37: =IF('Savings Summary'!J52=0,"",'Savings Summary'!J52) | N37: =IF('RESULTS kBtu'!H37=0,"",'RESULTS kBtu'!H37) | O37: ='Individual Measure List'!H50 -> #VALUE! | P37: ='Individual Measure List'!J50 -> #NUM! | Q37: ='Individual Measure List'!K50 -> #VALUE! | V37: =C37 | W37: =D37 | X37: =E37 | Y37: =I37 -> 0 | Z37: =J37 | AA37: =K37 | AB37: =L37 | AC37: =M37 | AD37: =O37 -> #VALUE! | AE37: =P37 -> #NUM! | AF37: =Q37 -> #VALUE! | AQ37: ='Individual Measure List'!G50 -> 0
A38: =SUM(B6:B38) -> 23 | B38: =IF(ISTEXT(D38)=TRUE,1,0) -> 1 | C38: ='Individual Measure List'!A51 | D38: ='Individual Measure List'!B51 | E38: ='EEM Data Entry'!D127 | F38: ='EEM Data Entry'!E127 | G38: ='EEM Data Entry'!G127 -> N/A | H38: ='EEM Data Entry'!F127 | I38: ='Individual Measure List'!F51 -> 0 | J38: =IF('Savings Summary'!D53=0,"",'Savings Summary'!D53) | K38: =IF('Savings Summary'!F53=0,"",'Savings Summary'!F53) | L38: =IF('Savings Summary'!H53=0,"",'Savings Summary'!H53) | M38: =IF('Savings Summary'!J53=0,"",'Savings Summary'!J53) | N38: =IF('RESULTS kBtu'!H38=0,"",'RESULTS kBtu'!H38) | O38: ='Individual Measure List'!H51 -> #VALUE! | P38: ='Individual Measure List'!J51 -> #NUM! | Q38: ='Individual Measure List'!K51 -> #VALUE! | V38: =C38 | W38: =D38 | X38: =E38 | Y38: =I38 -> 0 | Z38: =J38 | AA38: =K38 | AB38: =L38 | AC38: =M38 | AD38: =O38 -> #VALUE! | AE38: =P38 -> #NUM! | AF38: =Q38 -> #VALUE! | AQ38: ='Individual Measure List'!G51 -> 0
A39: =SUM(B6:B39) -> 24 | B39: =IF(ISTEXT(D39)=TRUE,1,0) -> 1 | C39: ='Individual Measure List'!A52 | D39: ='Individual Measure List'!B52 | E39: ='EEM Data Entry'!D128 | F39: ='EEM Data Entry'!E128 | G39: ='EEM Data Entry'!G128 -> N/A | H39: ='EEM Data Entry'!F128 | I39: ='Individual Measure List'!F52 -> 0 | J39: =IF('Savings Summary'!D54=0,"",'Savings Summary'!D54) | K39: =IF('Savings Summary'!F54=0,"",'Savings Summary'!F54) | L39: =IF('Savings Summary'!H54=0,"",'Savings Summary'!H54) | M39: =IF('Savings Summary'!J54=0,"",'Savings Summary'!J54) | N39: =IF('RESULTS kBtu'!H39=0,"",'RESULTS kBtu'!H39) | O39: ='Individual Measure List'!H52 -> #VALUE! | P39: ='Individual Measure List'!J52 -> #NUM! | Q39: ='Individual Measure List'!K52 -> #VALUE! | V39: =C39 | W39: =D39 | X39: =E39 | Y39: =I39 -> 0 | Z39: =J39 | AA39: =K39 | AB39: =L39 | AC39: =M39 | AD39: =O39 -> #VALUE! | AE39: =P39 -> #NUM! | AF39: =Q39 -> #VALUE! | AQ39: ='Individual Measure List'!G52 -> 0
A40: =SUM(B6:B40) -> 25 | B40: =IF(ISTEXT(D40)=TRUE,1,0) -> 1 | C40: ='Individual Measure List'!A53 | D40: ='Individual Measure List'!B53 | E40: ='EEM Data Entry'!D129 | F40: ='EEM Data Entry'!E129 | G40: ='EEM Data Entry'!G129 -> N/A | H40: ='EEM Data Entry'!F129 | I40: ='Individual Measure List'!F53 -> 0 | J40: =IF('Savings Summary'!D55=0,"",'Savings Summary'!D55) | K40: =IF('Savings Summary'!F55=0,"",'Savings Summary'!F55) | L40: =IF('Savings Summary'!H55=0,"",'Savings Summary'!H55) | M40: =IF('Savings Summary'!J55=0,"",'Savings Summary'!J55) | N40: =IF('RESULTS kBtu'!H40=0,"",'RESULTS kBtu'!H40) | O40: ='Individual Measure List'!H53 -> #VALUE! | P40: ='Individual Measure List'!J53 -> #NUM! | Q40: ='Individual Measure List'!K53 -> #VALUE! | V40: =C40 | W40: =D40 | X40: =E40 | Y40: =I40 -> 0 | Z40: =J40 | AA40: =K40 | AB40: =L40 | AC40: =M40 | AD40: =O40 -> #VALUE! | AE40: =P40 -> #NUM! | AF40: =Q40 -> #VALUE! | AQ40: ='Individual Measure List'!G53 -> 0
A41: =SUM(B6:B41) -> 26 | B41: =IF(ISTEXT(D41)=TRUE,1,0) -> 1 | C41: ='Individual Measure List'!A54 | D41: ='Individual Measure List'!B54 | E41: ='EEM Data Entry'!D130 | F41: ='EEM Data Entry'!E130 | G41: ='EEM Data Entry'!G130 -> N/A | H41: ='EEM Data Entry'!F130 | I41: ='Individual Measure List'!F54 -> 0 | J41: =IF('Savings Summary'!D56=0,"",'Savings Summary'!D56) | K41: =IF('Savings Summary'!F56=0,"",'Savings Summary'!F56) | L41: =IF('Savings Summary'!H56=0,"",'Savings Summary'!H56) | M41: =IF('Savings Summary'!J56=0,"",'Savings Summary'!J56) | N41: =IF('RESULTS kBtu'!H41=0,"",'RESULTS kBtu'!H41) | O41: ='Individual Measure List'!H54 -> #VALUE! | P41: ='Individual Measure List'!J54 -> #NUM! | Q41: ='Individual Measure List'!K54 -> #VALUE! | V41: =C41 | W41: =D41 | X41: =E41 | Y41: =I41 -> 0 | Z41: =J41 | AA41: =K41 | AB41: =L41 | AC41: =M41 | AD41: =O41 -> #VALUE! | AE41: =P41 -> #NUM! | AF41: =Q41 -> #VALUE! | AQ41: ='Individual Measure List'!G54 -> 0
A42: =SUM(B6:B42) -> 27 | B42: =IF(ISTEXT(D42)=TRUE,1,0) -> 1 | C42: ='Individual Measure List'!A55 | D42: ='Individual Measure List'!B55 | E42: ='EEM Data Entry'!D131 | F42: ='EEM Data Entry'!E131 | G42: ='EEM Data Entry'!G131 -> N/A | H42: ='EEM Data Entry'!F131 | I42: ='Individual Measure List'!F55 -> 0 | J42: =IF('Savings Summary'!D57=0,"",'Savings Summary'!D57) | K42: =IF('Savings Summary'!F57=0,"",'Savings Summary'!F57) | L42: =IF('Savings Summary'!H57=0,"",'Savings Summary'!H57) | M42: =IF('Savings Summary'!J57=0,"",'Savings Summary'!J57) | N42: =IF('RESULTS kBtu'!H42=0,"",'RESULTS kBtu'!H42) | O42: ='Individual Measure List'!H55 -> #VALUE! | P42: ='Individual Measure List'!J55 -> #NUM! | Q42: ='Individual Measure List'!K55 -> #VALUE! | V42: =C42 | W42: =D42 | X42: =E42 | Y42: =I42 -> 0 | Z42: =J42 | AA42: =K42 | AB42: =L42 | AC42: =M42 | AD42: =O42 -> #VALUE! | AE42: =P42 -> #NUM! | AF42: =Q42 -> #VALUE! | AQ42: ='Individual Measure List'!G55 -> 0
A43: =SUM(B6:B43) -> 28 | B43: =IF(ISTEXT(D43)=TRUE,1,0) -> 1 | C43: ='Individual Measure List'!A56 | D43: ='Individual Measure List'!B56 | E43: ='EEM Data Entry'!D132 | F43: ='EEM Data Entry'!E132 | G43: ='EEM Data Entry'!G132 -> N/A | H43: ='EEM Data Entry'!F132 | I43: ='Individual Measure List'!F56 -> 0 | J43: =IF('Savings Summary'!D58=0,"",'Savings Summary'!D58) | K43: =IF('Savings Summary'!F58=0,"",'Savings Summary'!F58) | L43: =IF('Savings Summary'!H58=0,"",'Savings Summary'!H58) | M43: =IF('Savings Summary'!J58=0,"",'Savings Summary'!J58) | N43: =IF('RESULTS kBtu'!H43=0,"",'RESULTS kBtu'!H43) | O43: ='Individual Measure List'!H56 -> #VALUE! | P43: ='Individual Measure List'!J56 -> #NUM! | Q43: ='Individual Measure List'!K56 -> #VALUE! | V43: =C43 | W43: =D43 | X43: =E43 | Y43: =I43 -> 0 | Z43: =J43 | AA43: =K43 | AB43: =L43 | AC43: =M43 | AD43: =O43 -> #VALUE! | AE43: =P43 -> #NUM! | AF43: =Q43 -> #VALUE! | AQ43: ='Individual Measure List'!G56 -> 0
A44: =SUM(B6:B44) -> 29 | B44: =IF(ISTEXT(D44)=TRUE,1,0) -> 1 | C44: ='Individual Measure List'!A57 | D44: ='Individual Measure List'!B57 | E44: ='EEM Data Entry'!D133 | F44: ='EEM Data Entry'!E133 | G44: ='EEM Data Entry'!G133 -> N/A | H44: ='EEM Data Entry'!F133 | I44: ='Individual Measure List'!F57 -> 0 | J44: =IF('Savings Summary'!D59=0,"",'Savings Summary'!D59) | K44: =IF('Savings Summary'!F59=0,"",'Savings Summary'!F59) | L44: =IF('Savings Summary'!H59=0,"",'Savings Summary'!H59) | M44: =IF('Savings Summary'!J59=0,"",'Savings Summary'!J59) | N44: =IF('RESULTS kBtu'!H44=0,"",'RESULTS kBtu'!H44) | O44: ='Individual Measure List'!H57 -> #VALUE! | P44: ='Individual Measure List'!J57 -> #NUM! | Q44: ='Individual Measure List'!K57 -> #VALUE! | V44: =C44 | W44: =D44 | X44: =E44 | Y44: =I44 -> 0 | Z44: =J44 | AA44: =K44 | AB44: =L44 | AC44: =M44 | AD44: =O44 -> #VALUE! | AE44: =P44 -> #NUM! | AF44: =Q44 -> #VALUE! | AQ44: ='Individual Measure List'!G57 -> 0
A45: =SUM(B6:B45) -> 30 | B45: =IF(ISTEXT(D45)=TRUE,1,0) -> 1 | C45: ='Individual Measure List'!A58 | D45: ='Individual Measure List'!B58 | E45: ='EEM Data Entry'!D134 | F45: ='EEM Data Entry'!E134 | G45: ='EEM Data Entry'!G134 -> N/A | H45: ='EEM Data Entry'!F134 | I45: ='Individual Measure List'!F58 -> 0 | J45: =IF('Savings Summary'!D60=0,"",'Savings Summary'!D60) | K45: =IF('Savings Summary'!F60=0,"",'Savings Summary'!F60) | L45: =IF('Savings Summary'!H60=0,"",'Savings Summary'!H60) | M45: =IF('Savings Summary'!J60=0,"",'Savings Summary'!J60) | N45: =IF('RESULTS kBtu'!H45=0,"",'RESULTS kBtu'!H45) | O45: ='Individual Measure List'!H58 -> #VALUE! | P45: ='Individual Measure List'!J58 -> #NUM! | Q45: ='Individual Measure List'!K58 -> #VALUE! | V45: =C45 | W45: =D45 | X45: =E45 | Y45: =I45 -> 0 | Z45: =J45 | AA45: =K45 | AB45: =L45 | AC45: =M45 | AD45: =O45 -> #VALUE! | AE45: =P45 -> #NUM! | AF45: =Q45 -> #VALUE! | AQ45: ='Individual Measure List'!G58 -> 0
C46: *Please see "Note Regarding Incentives" on first page of financial modeling section | V46: *Please see "Note Regarding Incentives" on first page of financial modeling section
...

Sheet RESULTS kBtu
A1: COPY AND PASTE TABLES BELOW INTO REPORT AS APPROPRIATE | P1: NO INCENTIVES
A3: ENVELOPE | P3: ENVELOPE
A5: EEM # | B5: Building Envelope Upgrades | C5: Capital Investment | D5: Estimated Incentive* | E5: Incentive Reference | F5: Estimated Net Cost | G5: Annual Energy Cost Savings | H5: Annual kBTU Savings | I5: Simple Payback (Years) | J5: IRR | K5: NPV | P5: =A5 -> EEM # | Q5: =B5 -> Building Envelope Upgrades | R5: =C5 -> Capital Investment | S5: =G5 -> Annual Energy Cost Savings | T5: =H5 -> Annual kBTU Savings | U5: =I5 -> Simple Payback (Years) | V5: =J5 -> IRR | W5: =K5 -> NPV
A6: ='Individual Measure List'!A8 | B6: ='Individual Measure List'!B8 | C6: ='EEM Data Entry'!D85 | D6: ='EEM Data Entry'!E85 | E6: ='EEM Data Entry'!G85 -> N/A | F6: ='EEM Data Entry'!F85 | G6: ='Individual Measure List'!F8 -> 0 | H6: ='Individual Measure List'!G8 -> 0 | I6: ='Individual Measure List'!H8 -> #VALUE! | J6: ='Individual Measure List'!J8 -> #NUM! | K6: ='Individual Measure List'!K8 -> #VALUE! | M6: Discount Rate | P6: =A6 | Q6: =B6 | R6: =C6 | S6: =G6 -> 0 | T6: =H6 -> 0 | U6: =I6 -> #VALUE! | V6: =J6 -> #NUM! | W6: =K6 -> #VALUE!
A7: ='Individual Measure List'!A9 | B7: ='Individual Measure List'!B9 | C7: ='EEM Data Entry'!D86 | D7: ='EEM Data Entry'!E86 | E7: ='EEM Data Entry'!G86 -> N/A | F7: ='EEM Data Entry'!F86 | G7: ='Individual Measure List'!F9 -> 0 | H7: ='Individual Measure List'!G9 -> 0 | I7: ='Individual Measure List'!H9 -> #VALUE! | J7: ='Individual Measure List'!J9 -> #NUM! | K7: ='Individual Measure List'!K9 -> #VALUE! | M7: Inflation | N7: ='Interest Rate'!C10 -> 0.034 | P7: =A7 | Q7: =B7 | R7: =C7 | S7: =G7 -> 0 | T7: =H7 -> 0 | U7: =I7 -> #VALUE! | V7: =J7 -> #NUM! | W7: =K7 -> #VALUE!
A8: ='Individual Measure List'!A10 | B8: ='Individual Measure List'!B10 | C8: ='EEM Data Entry'!D87 | D8: ='EEM Data Entry'!E87 | E8: ='EEM Data Entry'!G87 -> N/A | F8: ='EEM Data Entry'!F87 | G8: ='Individual Measure List'!F10 -> 0 | H8: ='Individual Measure List'!G10 -> 0 | I8: ='Individual Measure List'!H10 -> #VALUE! | J8: ='Individual Measure List'!J10 -> #NUM! | K8: ='Individual Measure List'!K10 -> #VALUE! | M8: Nominal Escalation Rate | N8: ='Interest Rate'!C12 -> 0 | P8: =A8 | Q8: =B8 | R8: =C8 | S8: =G8 -> 0 | T8: =H8 -> 0 | U8: =I8 -> #VALUE! | V8: =J8 -> #NUM! | W8: =K8 -> #VALUE!
A9: ='Individual Measure List'!A11 | B9: ='Individual Measure List'!B11 | C9: ='EEM Data Entry'!D88 | D9: ='EEM Data Entry'!E88 | E9: ='EEM Data Entry'!G88 -> N/A | F9: ='EEM Data Entry'!F88 | G9: ='Individual Measure List'!F11 -> 0 | H9: ='Individual Measure List'!G11 -> 0 | I9: ='Individual Measure List'!H11 -> #VALUE! | J9: ='Individual Measure List'!J11 -> #NUM! | K9: ='Individual Measure List'!K11 -> #VALUE! | M9: Discount Rate | N9: ='Interest Rate'!C14 -> 0.05 | P9: =A9 | Q9: =B9 | R9: =C9 | S9: =G9 -> 0 | T9: =H9 -> 0 | U9: =I9 -> #VALUE! | V9: =J9 -> #NUM! | W9: =K9 -> #VALUE!
A10: ='Individual Measure List'!A12 | B10: ='Individual Measure List'!B12 | C10: ='EEM Data Entry'!D89 | D10: ='EEM Data Entry'!E89 | E10: ='EEM Data Entry'!G89 -> N/A | F10: ='EEM Data Entry'!F89 | G10: ='Individual Measure List'!F12 -> 0 | H10: ='Individual Measure List'!G12 -> 0 | I10: ='Individual Measure List'!H12 -> #VALUE! | J10: ='Individual Measure List'!J12 -> #NUM! | K10: ='Individual Measure List'!K12 -> #VALUE! | M10: Adjusted Discount Rate | N10: ='Interest Rate'!B17 -> 0.05 | P10: =A10 | Q10: =B10 | R10: =C10 | S10: =G10 -> 0 | T10: =H10 -> 0 | U10: =I10 -> #VALUE! | V10: =J10 -> #NUM! | W10: =K10 -> #VALUE!
A11: ='Individual Measure List'!A13 | B11: ='Individual Measure List'!B13 | C11: ='EEM Data Entry'!D90 | D11: ='EEM Data Entry'!E90 | E11: ='EEM Data Entry'!G90 -> N/A | F11: ='EEM Data Entry'!F90 | G11: ='Individual Measure List'!F13 -> 0 | H11: ='Individual Measure List'!G13 -> 0 | I11: ='Individual Measure List'!H13 -> #VALUE! | J11: ='Individual Measure List'!J13 -> #NUM! | K11: ='Individual Measure List'!K13 -> #VALUE! | M11: *Calculated using the Nation Institute of Standards and Technology (NIST) Energy Escalation Rate Calculator | P11: =A11 | Q11: =B11 | R11: =C11 | S11: =G11 -> 0 | T11: =H11 -> 0 | U11: =I11 -> #VALUE! | V11: =J11 -> #NUM! | W11: =K11 -> #VALUE!
A12: ='Individual Measure List'!A14 | B12: ='Individual Measure List'!B14 | C12: ='EEM Data Entry'!D91 | D12: ='EEM Data Entry'!E91 | E12: ='EEM Data Entry'!G91 -> N/A | F12: ='EEM Data Entry'!F91 | G12: ='Individual Measure List'!F14 -> 0 | H12: ='Individual Measure List'!G14 -> 0 | I12: ='Individual Measure List'!H14 -> #VALUE! | J12: ='Individual Measure List'!J14 -> #NUM! | K12: ='Individual Measure List'!K14 -> #VALUE! | P12: =A12 | Q12: =B12 | R12: =C12 | S12: =G12 -> 0 | T12: =H12 -> 0 | U12: =I12 -> #VALUE! | V12: =J12 -> #NUM! | W12: =K12 -> #VALUE!
A13: ='Individual Measure List'!A15 | B13: ='Individual Measure List'!B15 | C13: ='EEM Data Entry'!D92 | D13: ='EEM Data Entry'!E92 | E13: ='EEM Data Entry'!G92 -> N/A | F13: ='EEM Data Entry'!F92 | G13: ='Individual Measure List'!F15 -> 0 | H13: ='Individual Measure List'!G15 -> 0 | I13: ='Individual Measure List'!H15 -> #VALUE! | J13: ='Individual Measure List'!J15 -> #NUM! | K13: ='Individual Measure List'!K15 -> #VALUE! | P13: =A13 | Q13: =B13 | R13: =C13 | S13: =G13 -> 0 | T13: =H13 -> 0 | U13: =I13 -> #VALUE! | V13: =J13 -> #NUM! | W13: =K13 -> #VALUE!
A14: ='Individual Measure List'!A16 | B14: ='Individual Measure List'!B16 | C14: ='EEM Data Entry'!D93 | D14: ='EEM Data Entry'!E93 | E14: ='EEM Data Entry'!G93 -> N/A | F14: ='EEM Data Entry'!F93 | G14: ='Individual Measure List'!F16 -> 0 | H14: ='Individual Measure List'!G16 -> 0 | I14: ='Individual Measure List'!H16 -> #VALUE! | J14: ='Individual Measure List'!J16 -> #NUM! | K14: ='Individual Measure List'!K16 -> #VALUE! | P14: =A14 | Q14: =B14 | R14: =C14 | S14: =G14 -> 0 | T14: =H14 -> 0 | U14: =I14 -> #VALUE! | V14: =J14 -> #NUM! | W14: =K14 -> #VALUE!
A15: ='Individual Measure List'!A17 | B15: ='Individual Measure List'!B17 | C15: ='EEM Data Entry'!D94 | D15: ='EEM Data Entry'!E94 | E15: ='EEM Data Entry'!G94 -> N/A | F15: ='EEM Data Entry'!F94 | G15: ='Individual Measure List'!F17 -> 0 | H15: ='Individual Measure List'!G17 -> 0 | I15: ='Individual Measure List'!H17 -> #VALUE! | J15: ='Individual Measure List'!J17 -> #NUM! | K15: ='Individual Measure List'!K17 -> #VALUE! | P15: =A15 | Q15: =B15 | R15: =C15 | S15: =G15 -> 0 | T15: =H15 -> 0 | U15: =I15 -> #VALUE! | V15: =J15 -> #NUM! | W15: =K15 -> #VALUE!
A16: *Please see "Note Regarding Incentives" on first page of financial modeling section | P16: *Please see "Note Regarding Incentives" on first page of financial modeling section
A18: MECHANICAL | P18: MECHANICAL
A20: EEM # | B20: Mechanical System Upgrades | C20: Capital Investment | D20: Estimated Incentive* | E20: Incentive Reference | F20: Estimated Net Cost | G20: Annual Energy Cost Savings | H20: Annual kBTU Savings | I20: Simple Payback (Years) | J20: IRR | K20: NPV | P20: =A20 -> EEM # | Q20: =B20 -> Mechanical System Upgrades | R20: =C20 -> Capital Investment | S20: =G20 -> Annual Energy Cost Savings | T20: =H20 -> Annual kBTU Savings | U20: =I20 -> Simple Payback (Years) | V20: =J20 -> IRR | W20: =K20 -> NPV
A21: ='Individual Measure List'!A33 | B21: ='Individual Measure List'!B33 | C21: ='EEM Data Entry'!D110 | D21: ='EEM Data Entry'!E110 | E21: ='EEM Data Entry'!G110 -> N/A | F21: ='EEM Data Entry'!F110 | G21: ='Individual Measure List'!F33 -> 0 | H21: ='Individual Measure List'!G33 -> 0 | I21: ='Individual Measure List'!H33 -> #VALUE! | J21: ='Individual Measure List'!J33 -> #NUM! | K21: ='Individual Measure List'!K33 -> #VALUE! | P21: =A21 | Q21: =B21 | R21: =C21 | S21: =G21 -> 0 | T21: =H21 -> 0 | U21: =I21 -> #VALUE! | V21: =J21 -> #NUM! | W21: =K21 -> #VALUE!
A22: ='Individual Measure List'!A34 | B22: ='Individual Measure List'!B34 | C22: ='EEM Data Entry'!D111 | D22: ='EEM Data Entry'!E111 | E22: ='EEM Data Entry'!G111 -> N/A | F22: ='EEM Data Entry'!F111 | G22: ='Individual Measure List'!F34 -> 0 | H22: ='Individual Measure List'!G34 -> 0 | I22: ='Individual Measure List'!H34 -> #VALUE! | J22: ='Individual Measure List'!J34 -> #NUM! | K22: ='Individual Measure List'!K34 -> #VALUE! | P22: =A22 | Q22: =B22 | R22: =C22 | S22: =G22 -> 0 | T22: =H22 -> 0 | U22: =I22 -> #VALUE! | V22: =J22 -> #NUM! | W22: =K22 -> #VALUE!
A23: ='Individual Measure List'!A35 | B23: ='Individual Measure List'!B35 | C23: ='EEM Data Entry'!D112 | D23: ='EEM Data Entry'!E112 | E23: ='EEM Data Entry'!G112 -> N/A | F23: ='EEM Data Entry'!F112 | G23: ='Individual Measure List'!F35 -> 0 | H23: ='Individual Measure List'!G35 -> 0 | I23: ='Individual Measure List'!H35 -> #VALUE! | J23: ='Individual Measure List'!J35 -> #NUM! | K23: ='Individual Measure List'!K35 -> #VALUE! | P23: =A23 | Q23: =B23 | R23: =C23 | S23: =G23 -> 0 | T23: =H23 -> 0 | U23: =I23 -> #VALUE! | V23: =J23 -> #NUM! | W23: =K23 -> #VALUE!
A24: ='Individual Measure List'!A36 | B24: ='Individual Measure List'!B36 | C24: ='EEM Data Entry'!D113 | D24: ='EEM Data Entry'!E113 | E24: ='EEM Data Entry'!G113 -> N/A | F24: ='EEM Data Entry'!F113 | G24: ='Individual Measure List'!F36 -> 0 | H24: ='Individual Measure List'!G36 -> 0 | I24: ='Individual Measure List'!H36 -> #VALUE! | J24: ='Individual Measure List'!J36 -> #NUM! | K24: ='Individual Measure List'!K36 -> #VALUE! | P24: =A24 | Q24: =B24 | R24: =C24 | S24: =G24 -> 0 | T24: =H24 -> 0 | U24: =I24 -> #VALUE! | V24: =J24 -> #NUM! | W24: =K24 -> #VALUE!
