Workbook

Sheet ALL
A1: CSV PARAMETER | B1: DESCRIPTION | C1: SAMPLE (taken from different sites)
A2: BUILDING_REFERENCE_NUMBER | B2: Unique 10-digit identifier for the property, generated by the SEPCR to enable the EPC lodgement process even where there is no current matching UPRN for the assessed property extents (building or building unit). Not the same as the Unique Property Reference Number available from the One Scotland Gazetteer. | C2: 1001829059
A3: OSG_REFERENCE_NUMBER | B3: Unique 9-12-digit property reference number assigned to a building by local authority data custodians and recorded centrally on the One Scotland Gazetteer: Energy Performance of Buildings Data England and Wales (opendatacommunities.org). | C3: 122009928
A4: ADDRESS1 | B4: First line of the building address | C4: 11 CULCREUCH AVENUE
A5: ADDRESS2 | B5: Second line of the building address | C5: FINTRY
A6: ADDRESS3 | B6: Third line of the building address. Note that ADDRESS3 is assigned as POST_TOWN | C6: GLASGOW
A7: POSTCODE | B7: The postcode of the property | C7: G63 0YB
A8: LATITUDE | B8: Latitude of site (aquired with Google Maps API) | C8: 56.05605329999999
A9: LONGITUDE | B9: Longitude of site (aquired with Google Maps API) | C9: -4.2246704
A10: INSPECTION_DATE | B10: Date on which assessment of the energy performance of the building was undertaken | C10: 45798
A11: TYPE_OF_ASSESSMENT | B11: Tool used (SAP, RdSAP) and whether assessment is for new or existing dwelling. | C11: RdSAP, existing dwelling
A12: LODGEMENT_DATE | B12: Date on which the data from the energy performance assessment was lodged to the Scottish EPC Register | C12: 45800
A13: ENERGY_CONSUMPTION_CURRENT | B13: Reports Primary Energy - the amount of energy required at source, before conversion and transmission, to meet the calculated energy demand of the dwelling (Units: kWh/m²/year). | C13: 271
A14: TOTAL_FLOOR_AREA | B14: The total floor area of the dwelling. This excludes any unheated ancillary buildings. (Units: m²) | C14: 93
A15: 3_YR_ENERGY_COST_CURRENT | B15: Calculation illustrating the total energy cost for heating, cooling, lighting, and ventilating the building. Based on standardised occupancy patterns and fuel costs. (Units: £) | C15: 6237
A16: 3_YR_ENERGY_SAVINGS_POTENTIAL | B16: Calculation illustrating the energy cost saving that may be achieved if the listed improvement measures are carried out. Based on standardised occupancy patterns and fuel costs. (Units: £) | C16: 1311
A17: CURRENT_ENERGY_EFFICIENCY | B17: Current energy cost rating (EER or ‘SAP rating’) for the building which is calculated using both the energy efficiency of the building and the cost of fuels used. | C17: 63
A18: CURRENT_ENERGY_RATING | B18: Current Energy Efficiency Rating expressed on a Scale of G to A, with A being the highest (best) rating band. | C18: D
A19: POTENTIAL_ENERGY_EFFICIENCY | B19: Potential energy cost rating for the building, after application of the listed improvement measures, which is again calculated using both the energy efficiency of the improved building and the cost of fuels used. | C19: 81
A20: POTENTIAL_ENERGY_RATING | B20: Potential Energy Efficiency Rating expressed on a Scale of G to A, with A being the highest (best) rating band. | C20: B
A21: ENVIRONMENT_IMPACT_CURRENT | B21: Current environmental impact for the building which is calculated using the emissions associated with the energy use of the building. | C21: 53
A22: CURRENT_ENVIRONMENTAL_RATING | B22: Current Environmental Impact Rating expressed on a Scale of G to A, with A being the highest (best) rating band. | C22: E
A23: ENVIRONMENT_IMPACT_POTENTIAL | B23: Potential environmental impact for the building, after application of the listed improvement measures, which is again calculated using the emissions associated with the energy use of the building. | C23: 72
A24: POTENTIAL_ENVIRONMENTAL_RATING | B24: Potential Environmental Impact Rating expressed on a Scale of G to A, with A being the highest (best) rating band. | C24: C
A25: CO2_EMISS_CURR_PER_FLOOR_AREA | B25: Annual CO2 equivalent emissions per square metre of floor area (units: kg.CO2e/m²/yr) | C25: 59
A26: IMPROVEMENTS | B26: A list of the improvement measures identified as relevant to the building at the date of assessment. These measures are drawn from the list of measures published in Appendix T of the current SAP 2012 October 2013 with RdSAP 19 Dec 2014 specification. Improvement measures are listed sequentially under a single data entry in the following format: ‘Description; Typical saving; Energy Rating after improvement; Environmental Rating after improvement; Green Deal eligible.’ Each measure reported is separated by a vertical line [ “|” - ASCII (decimal) 124] | C26: ; Indicative Cost: ¬£300 - ¬£600; Typical Saving: 77; Energy Rating after improvement: D 64; Environmental Rating after improvement: D 55; Green Deal Eligible: Y | Description: Solar photovoltaic panels, 2.5 kWp; Indicative Cost: ¬£3,500 - ¬£5,500; Typical Saving: 389; Energy Rating after improvement: B 81; Environmental Rating after improvement: C 72; Green Deal Eligible: Y | Description: Floor insulation (solid floor); Indicative Cost: ¬£4,000 - ¬£6,000; Typical Saving: 186; Energy Rating after improvement: D 67; Environmental Rating after improvement: D 59; Green Deal Eligible: Y | Description: Solar water heating; Indicative Cost: ¬£4,000 - ¬£6,000; Typical Saving: 173; Energy Rating after improvement: C 71; Environmental Rating after improvement: D 64; Green Deal Eligible: Y |
A27: WALL_DESCRIPTION | B27: Summary of the performance of this building element, reported in the following format: ‘Description; Energy Efficiency Rating; Environmental Efficiency Rating.’ Both ratings elements are reported on a scale of 1 to 5 (very poor, poor, average, good, very good). Note: where a dwelling has more than one type of this element, multiple elements can be reported. Each element reported is separated by “|” [ASCII (decimal) 124] | C27: System built, with external insulation
A28: WALL_ENERGY_EFF | B28: Summary of the performance of this building element, reported in the following format: ‘Description; Energy Efficiency Rating; Environmental Efficiency Rating.’ Both ratings elements are reported on a scale of 1 to 5 (very poor, poor, average, good, very good). Note: where a dwelling has more than one type of this element, multiple elements can be reported. Each element reported is separated by “|” [ASCII (decimal) 124] | C28: Good
A29: WALL_ENV_EFF | B29: Summary of the performance of this building element, reported in the following format: ‘Description; Energy Efficiency Rating; Environmental Efficiency Rating.’ Both ratings elements are reported on a scale of 1 to 5 (very poor, poor, average, good, very good). Note: where a dwelling has more than one type of this element, multiple elements can be reported. Each element reported is separated by “|” [ASCII (decimal) 124] | C29: Good
A30: ROOF_DESCRIPTION | B30: Summary of the performance of this building element, reported in the following format: ‘Description; Energy Efficiency Rating; Environmental Efficiency Rating.’ Both ratings elements are reported on a scale of 1 to 5 (very poor, poor, average, good, very good). Note: where a dwelling has more than one type of this element, multiple elements can be reported. Each element reported is separated by “|” [ASCII (decimal) 124] | C30: Pitched, 250 mm loft insulation
A31: ROOF_ENERGY_EFF | B31: Summary of the performance of this building element, reported in the following format: ‘Description; Energy Efficiency Rating; Environmental Efficiency Rating.’ Both ratings elements are reported on a scale of 1 to 5 (very poor, poor, average, good, very good). Note: where a dwelling has more than one type of this element, multiple elements can be reported. Each element reported is separated by “|” [ASCII (decimal) 124] | C31: Good
A32: ROOF_ENV_EFF | B32: Summary of the performance of this building element, reported in the following format: ‘Description; Energy Efficiency Rating; Environmental Efficiency Rating.’ Both ratings elements are reported on a scale of 1 to 5 (very poor, poor, average, good, very good). Note: where a dwelling has more than one type of this element, multiple elements can be reported. Each element reported is separated by “|” [ASCII (decimal) 124] | C32: Good
A33: FLOOR_DESCRIPTION | B33: Summary of the performance of this building element, reported in the following format: ‘Description; Energy Efficiency Rating; Environmental Efficiency Rating.’ Both ratings elements are reported on a scale of 1 to 5 (very poor, poor, average, good, very good). Note: where a dwelling has more than one type of this element, multiple elements can be reported. Each element reported is separated by “|” [ASCII (decimal) 124] | C33: Solid, no insulation (assumed)
A34: FLOOR_ENERGY_EFF | B34: Summary of the performance of this building element, reported in the following format: ‘Description; Energy Efficiency Rating; Environmental Efficiency Rating.’ Both ratings elements are reported on a scale of 1 to 5 (very poor, poor, average, good, very good). Note: where a dwelling has more than one type of this element, multiple elements can be reported. Each element reported is separated by “|” [ASCII (decimal) 124] | C34: N/A
A35: FLOOR_ENV_EFF | B35: Summary of the performance of this building element, reported in the following format: ‘Description; Energy Efficiency Rating; Environmental Efficiency Rating.’ Both ratings elements are reported on a scale of 1 to 5 (very poor, poor, average, good, very good). Note: where a dwelling has more than one type of this element, multiple elements can be reported. Each element reported is separated by “|” [ASCII (decimal) 124] | C35: N/A
A36: WINDOWS_DESCRIPTION | B36: Summary of the performance of this building element, reported in the following format: ‘Description; Energy Efficiency Rating; Environmental Efficiency Rating.’ Both ratings elements are reported on a scale of 1 to 5 (very poor, poor, average, good, very good). Note: where a dwelling has more than one type of this element, multiple elements can be reported. Each element reported is separated by “|” [ASCII (decimal) 124] | C36: Description: Fully double glazed
A37: WINDOWS_ENERGY_EFF | B37: Summary of the performance of this building element, reported in the following format: ‘Description; Energy Efficiency Rating; Environmental Efficiency Rating.’ Both ratings elements are reported on a scale of 1 to 5 (very poor, poor, average, good, very good). Note: where a dwelling has more than one type of this element, multiple elements can be reported. Each element reported is separated by “|” [ASCII (decimal) 124] | C37: Average
... A56: AIR_TIGHTNESS_ENV_EFF | B56: Summary of the performance of this building element, reported in the following format: ‘Description; Energy Efficiency Rating; Environmental Efficiency Rating.’ Both ratings elements are reported on a scale of 1 to 5 (very poor, poor, average, good, very good). Note: where a dwelling has more than one type of this element, multiple elements can be reported. Each element reported is separated by “|” [ASCII (decimal) 124] | C56: Good
A57: CO2_EMISSIONS_CURRENT | B57: The total annual emissions reduction for the building based upon the calculated energy demand for heating, cooling, lighting, and ventilating the building. (Units: tonnes per year) | C57: 5.5
A58: CO2_EMISSIONS_POTENTIAL | B58: Calculation illustrating the total annual emissions reduction for the building if the identified improvement measures are carried out. (Units: tonnes per year) | C58: 2
...

Sheet Categorical For Modeling
A1: CSV PARAMETER | B1: DESCRIPTION | C1: SAMPLE (taken from different sites) | D1: Categorical Values (complete list)
A2: BUILDING_REFERENCE_NUMBER | B2: Unique 10-digit identifier for the property, generated by the SEPCR to enable the EPC lodgement process even where there is no current matching UPRN for the assessed property extents (building or building unit). Not the same as the Unique Property Reference Number available from the One Scotland Gazetteer. | C2: 1001829059 | D2: =IFERROR(VLOOKUP(A2,'Unique Values'!$A$2:$B$57,2,FALSE),"")
A3: OSG_REFERENCE_NUMBER | B3: Unique 9-12-digit property reference number assigned to a building by local authority data custodians and recorded centrally on the One Scotland Gazetteer: Energy Performance of Buildings Data England and Wales (opendatacommunities.org). | C3: 122009928 | D3: =IFERROR(VLOOKUP(A3,'Unique Values'!$A$2:$B$57,2,FALSE),"")
A4: ADDRESS1 | B4: First line of the building address | C4: 11 CULCREUCH AVENUE | D4: =IFERROR(VLOOKUP(A4,'Unique Values'!$A$2:$B$57,2,FALSE),"")
A5: ADDRESS2 | B5: Second line of the building address | C5: FINTRY | D5: =IFERROR(VLOOKUP(A5,'Unique Values'!$A$2:$B$57,2,FALSE),"")
A6: ADDRESS3 | B6: Third line of the building address. Note that ADDRESS3 is assigned as POST_TOWN | C6: GLASGOW | D6: =IFERROR(VLOOKUP(A6,'Unique Values'!$A$2:$B$57,2,FALSE),"")
A7: POSTCODE | B7: The postcode of the property | C7: G63 0YB | D7: =IFERROR(VLOOKUP(A7,'Unique Values'!$A$2:$B$57,2,FALSE),"")
A8: LATITUDE | B8: Latitude of site (aquired with Google Maps API) | C8: 56.05605329999999 | D8: =IFERROR(VLOOKUP(A8,'Unique Values'!$A$2:$B$57,2,FALSE),"")
A9: LONGITUDE | B9: Longitude of site (aquired with Google Maps API) | C9: -4.2246704 | D9: =IFERROR(VLOOKUP(A9,'Unique Values'!$A$2:$B$57,2,FALSE),"")
A10: INSPECTION_DATE | B10: Date on which assessment of the energy performance of the building was undertaken | C10: 45798 | D10: =IFERROR(VLOOKUP(A10,'Unique Values'!$A$2:$B$57,2,FALSE),"")
A11: TYPE_OF_ASSESSMENT | B11: Tool used (SAP, RdSAP) and whether assessment is for new or existing dwelling. | C11: RdSAP, existing dwelling | D11: =IFERROR(VLOOKUP(A11,'Unique Values'!$A$2:$B$57,2,FALSE),"")
A12: LODGEMENT_DATE | B12: Date on which the data from the energy performance assessment was lodged to the Scottish EPC Register | C12: 45800 | D12: =IFERROR(VLOOKUP(A12,'Unique Values'!$A$2:$B$57,2,FALSE),"")
A13: ENERGY_CONSUMPTION_CURRENT | B13: Reports Primary Energy - the amount of energy required at source, before conversion and transmission, to meet the calculated energy demand of the dwelling (Units: kWh/m²/year). | C13: 271 | D13: =IFERROR(VLOOKUP(A13,'Unique Values'!$A$2:$B$57,2,FALSE),"")
A14: TOTAL_FLOOR_AREA | B14: The total floor area of the dwelling. This excludes any unheated ancillary buildings. (Units: m²) | C14: 93 | D14: =IFERROR(VLOOKUP(A14,'Unique Values'!$A$2:$B$57,2,FALSE),"")
A15: 3_YR_ENERGY_COST_CURRENT | B15: Calculation illustrating the total energy cost for heating, cooling, lighting, and ventilating the building. Based on standardised occupancy patterns and fuel costs. (Units: £) | C15: 6237 | D15: =IFERROR(VLOOKUP(A15,'Unique Values'!$A$2:$B$57,2,FALSE),"")
A16: 3_YR_ENERGY_SAVINGS_POTENTIAL | B16: Calculation illustrating the energy cost saving that may be achieved if the listed improvement measures are carried out. Based on standardised occupancy patterns and fuel costs. (Units: £) | C16: 1311 | D16: =IFERROR(VLOOKUP(A16,'Unique Values'!$A$2:$B$57,2,FALSE),"")
A17: CURRENT_ENERGY_EFFICIENCY | B17: Current energy cost rating (EER or ‘SAP rating’) for the building which is calculated using both the energy efficiency of the building and the cost of fuels used. | C17: 63 | D17: =IFERROR(VLOOKUP(A17,'Unique Values'!$A$2:$B$57,2,FALSE),"")
A18: CURRENT_ENERGY_RATING | B18: Current Energy Efficiency Rating expressed on a Scale of G to A, with A being the highest (best) rating band. | C18: D | D18: =IFERROR(VLOOKUP(A18,'Unique Values'!$A$2:$B$57,2,FALSE),"") -> A; B; C; D; E; F; G
A19: POTENTIAL_ENERGY_EFFICIENCY | B19: Potential energy cost rating for the building, after application of the listed improvement measures, which is again calculated using both the energy efficiency of the improved building and the cost of fuels used. | C19: 81 | D19: =IFERROR(VLOOKUP(A19,'Unique Values'!$A$2:$B$57,2,FALSE),"")
A20: POTENTIAL_ENERGY_RATING | B20: Potential Energy Efficiency Rating expressed on a Scale of G to A, with A being the highest (best) rating band. | C20: B | D20: =IFERROR(VLOOKUP(A20,'Unique Values'!$A$2:$B$57,2,FALSE),"") -> A; B; C; D; E
A21: ENVIRONMENT_IMPACT_CURRENT | B21: Current environmental impact for the building which is calculated using the emissions associated with the energy use of the building. | C21: 53 | D21: =IFERROR(VLOOKUP(A21,'Unique Values'!$A$2:$B$57,2,FALSE),"")
A22: CURRENT_ENVIRONMENTAL_RATING | B22: Current Environmental Impact Rating expressed on a Scale of G to A, with A being the highest (best) rating band. | C22: E | D22: =IFERROR(VLOOKUP(A22,'Unique Values'!$A$2:$B$57,2,FALSE),"") -> A; B; C; D; E; F; G
A23: ENVIRONMENT_IMPACT_POTENTIAL | B23: Potential environmental impact for the building, after application of the listed improvement measures, which is again calculated using the emissions associated with the energy use of the building. | C23: 72 | D23: =IFERROR(VLOOKUP(A23,'Unique Values'!$A$2:$B$57,2,FALSE),"")
A24: POTENTIAL_ENVIRONMENTAL_RATING | B24: Potential Environmental Impact Rating expressed on a Scale of G to A, with A being the highest (best) rating band. | C24: C | D24: =IFERROR(VLOOKUP(A24,'Unique Values'!$A$2:$B$57,2,FALSE),"") -> A; B; C; D; E
A25: CO2_EMISS_CURR_PER_FLOOR_AREA | B25: Annual CO2 equivalent emissions per square metre of floor area (units: kg.CO2e/m²/yr) | C25: 59 | D25: =IFERROR(VLOOKUP(A25,'Unique Values'!$A$2:$B$57,2,FALSE),"")
A26: IMPROVEMENTS | B26: A list of the improvement measures identified as relevant to the building at the date of assessment. These measures are drawn from the list of measures published in Appendix T of the current SAP 2012 October 2013 with RdSAP 19 Dec 2014 specification. Improvement measures are listed sequentially under a single data entry in the following format: ‘Description; Typical saving; Energy Rating after improvement; Environmental Rating after improvement; Green Deal eligible.’ Each measure reported is separated by a vertical line [ “|” - ASCII (decimal) 124] | C26: ; Indicative Cost: ¬£300 - ¬£600; Typical Saving: 77; Energy Rating after improvement: D 64; Environmental Rating after improvement: D 55; Green Deal Eligible: Y | Description: Solar photovoltaic panels, 2.5 kWp; Indicative Cost: ¬£3,500 - ¬£5,500; Typical Saving: 389; Energy Rating after improvement: B 81; Environmental Rating after improvement: C 72; Green Deal Eligible: Y | Description: Floor insulation (solid floor); Indicative Cost: ¬£4,000 - ¬£6,000; Typical Saving: 186; Energy Rating after improvement: D 67; Environmental Rating after improvement: D 59; Green Deal Eligible: Y | Description: Solar water heating; Indicative Cost: ¬£4,000 - ¬£6,000; Typical Saving: 173; Energy Rating after improvement: C 71; Environmental Rating after improvement: D 64; Green Deal Eligible: Y | | D26: =IFERROR(VLOOKUP(A26,'Unique Values'!$A$2:$B$57,2,FALSE),"")
A27: WALL_DESCRIPTION | B27: Summary of the performance of this building element, reported in the following format: ‘Description; Energy Efficiency Rating; Environmental Efficiency Rating.’ Both ratings elements are reported on a scale of 1 to 5 (very poor, poor, average, good, very good). Note: where a dwelling has more than one type of this element, multiple elements can be reported. Each element reported is separated by “|” [ASCII (decimal) 124] | C27: System built, with external insulation | D27: =IFERROR(VLOOKUP(A27,'Unique Values'!$A$2:$B$57,2,FALSE),"") -> Average thermal transmittance 0.12 W/m¬≤K; Average thermal transmittance 0.13 W/m¬≤K; Average thermal transmittance 0.21 W/m¬≤K; Cavity wall, as built, insulated (assumed); Cavity wall, as built, no insulation (assumed); Cavity wall, as built, partial insulation (assumed); Cavity wall, filled cavity; Cavity wall, with external insulation; Granite or whinstone, as built, insulated (assumed); Granite or whinstone, as built, no insulation (assumed); Granite or whinstone, with internal insulation; Park home wall, as built; Park home wall, with external insulation; Sandstone or limestone, as built, insulated (assumed); Sandstone or limestone, as built, no insulation (assumed); Sandstone or limestone, with internal insulation; Solid brick, as built, no insulation (assumed); System built, as built, insulated (assumed); System built, as built, no insulation (assumed); System built, with external insulation; Timber frame, as built, insulated (assumed); Timber frame, as built, partial insulation (assumed); Timber frame, with additional insulation
A28: WALL_ENERGY_EFF | B28: Summary of the performance of this building element, reported in the following format: ‘Description; Energy Efficiency Rating; Environmental Efficiency Rating.’ Both ratings elements are reported on a scale of 1 to 5 (very poor, poor, average, good, very good). Note: where a dwelling has more than one type of this element, multiple elements can be reported. Each element reported is separated by “|” [ASCII (decimal) 124] | C28: Good | D28: =IFERROR(VLOOKUP(A28,'Unique Values'!$A$2:$B$57,2,FALSE),"") -> Average; Good; Poor; Very Good; Very Poor
A29: WALL_ENV_EFF | B29: Summary of the performance of this building element, reported in the following format: ‘Description; Energy Efficiency Rating; Environmental Efficiency Rating.’ Both ratings elements are reported on a scale of 1 to 5 (very poor, poor, average, good, very good). Note: where a dwelling has more than one type of this element, multiple elements can be reported. Each element reported is separated by “|” [ASCII (decimal) 124] | C29: Good | D29: =IFERROR(VLOOKUP(A29,'Unique Values'!$A$2:$B$57,2,FALSE),"") -> Average; Good; Poor; Very Good; Very Poor
A30: ROOF_DESCRIPTION | B30: Summary of the performance of this building element, reported in the following format: ‘Description; Energy Efficiency Rating; Environmental Efficiency Rating.’ Both ratings elements are reported on a scale of 1 to 5 (very poor, poor, average, good, very good). Note: where a dwelling has more than one type of this element, multiple elements can be reported. Each element reported is separated by “|” [ASCII (decimal) 124] | C30: Pitched, 250 mm loft insulation | D30: =IFERROR(VLOOKUP(A30,'Unique Values'!$A$2:$B$57,2,FALSE),"") -> (another dwelling above); Average thermal transmittance 0.10 W/m¬≤K; Average thermal transmittance 0.13 W/m¬≤K; Average thermal transmittance 0.15 W/m¬≤K; Flat, insulated; Flat, insulated (assumed); Flat, limited insulation (assumed); Flat, no insulation (assumed); Pitched, 100 mm loft insulation; Pitched, 150 mm loft insulation; Pitched, 200 mm loft insulation; Pitched, 250 mm loft insulation; Pitched, 270 mm loft insulation; Pitched, 300 mm loft insulation; Pitched, 350 mm loft insulation; Pitched, 400+ mm loft insulation; Pitched, insulated (assumed); Pitched, insulated at rafters; Pitched, limited insulation (assumed); Pitched, no insulation; Pitched, no insulation (assumed); Roof room(s), ceiling insulated; Roof room(s), insulated; Roof room(s), insulated (assumed); Roof room(s), limited insulation (assumed); Roof room(s), no insulation (assumed)
A31: ROOF_ENERGY_EFF | B31: Summary of the performance of this building element, reported in the following format: ‘Description; Energy Efficiency Rating; Environmental Efficiency Rating.’ Both ratings elements are reported on a scale of 1 to 5 (very poor, poor, average, good, very good). Note: where a dwelling has more than one type of this element, multiple elements can be reported. Each element reported is separated by “|” [ASCII (decimal) 124] | C31: Good | D31: =IFERROR(VLOOKUP(A31,'Unique Values'!$A$2:$B$57,2,FALSE),"") -> Average; Good; N/A; Poor; Very Good; Very Poor
A32: ROOF_ENV_EFF | B32: Summary of the performance of this building element, reported in the following format: ‘Description; Energy Efficiency Rating; Environmental Efficiency Rating.’ Both ratings elements are reported on a scale of 1 to 5 (very poor, poor, average, good, very good). Note: where a dwelling has more than one type of this element, multiple elements can be reported. Each element reported is separated by “|” [ASCII (decimal) 124] | C32: Good | D32: =IFERROR(VLOOKUP(A32,'Unique Values'!$A$2:$B$57,2,FALSE),"") -> Average; Good; N/A; Poor; Very Good; Very Poor
A33: FLOOR_DESCRIPTION | B33: Summary of the performance of this building element, reported in the following format: ‘Description; Energy Efficiency Rating; Environmental Efficiency Rating.’ Both ratings elements are reported on a scale of 1 to 5 (very poor, poor, average, good, very good). Note: where a dwelling has more than one type of this element, multiple elements can be reported. Each element reported is separated by “|” [ASCII (decimal) 124] | C33: Solid, no insulation (assumed) | D33: =IFERROR(VLOOKUP(A33,'Unique Values'!$A$2:$B$57,2,FALSE),"") -> (another dwelling below); Average thermal transmittance 0.12 W/m¬≤K; Average thermal transmittance 0.14 W/m¬≤K; Average thermal transmittance 0.15 W/m¬≤K; Solid, insulated; Solid, insulated (assumed); Solid, no insulation (assumed); Suspended, insulated; Suspended, insulated (assumed); Suspended, limited insulation (assumed); Suspended, no insulation (assumed); To unheated space, insulated (assumed); To unheated space, no insulation (assumed)
A34: FLOOR_ENERGY_EFF | B34: Summary of the performance of this building element, reported in the following format: ‘Description; Energy Efficiency Rating; Environmental Efficiency Rating.’ Both ratings elements are reported on a scale of 1 to 5 (very poor, poor, average, good, very good). Note: where a dwelling has more than one type of this element, multiple elements can be reported. Each element reported is separated by “|” [ASCII (decimal) 124] | C34: N/A | D34: =IFERROR(VLOOKUP(A34,'Unique Values'!$A$2:$B$57,2,FALSE),"") -> N/A; Very Good
A35: FLOOR_ENV_EFF | B35: Summary of the performance of this building element, reported in the following format: ‘Description; Energy Efficiency Rating; Environmental Efficiency Rating.’ Both ratings elements are reported on a scale of 1 to 5 (very poor, poor, average, good, very good). Note: where a dwelling has more than one type of this element, multiple elements can be reported. Each element reported is separated by “|” [ASCII (decimal) 124] | C35: N/A | D35: =IFERROR(VLOOKUP(A35,'Unique Values'!$A$2:$B$57,2,FALSE),"") -> N/A; Very Good
A36: WINDOWS_DESCRIPTION | B36: Summary of the performance of this building element, reported in the following format: ‘Description; Energy Efficiency Rating; Environmental Efficiency Rating.’ Both ratings elements are reported on a scale of 1 to 5 (very poor, poor, average, good, very good). Note: where a dwelling has more than one type of this element, multiple elements can be reported. Each element reported is separated by “|” [ASCII (decimal) 124] | C36: Description: Fully double glazed | D36: =IFERROR(VLOOKUP(A36,'Unique Values'!$A$2:$B$57,2,FALSE),"") -> Description: Fully double glazed; Description: Fully triple glazed; Description: High performance glazing; Description: Mostly double glazing; Description: Partial double glazing; Description: Some double glazing
A37: WINDOWS_ENERGY_EFF | B37: Summary of the performance of this building element, reported in the following format: ‘Description; Energy Efficiency Rating; Environmental Efficiency Rating.’ Both ratings elements are reported on a scale of 1 to 5 (very poor, poor, average, good, very good). Note: where a dwelling has more than one type of this element, multiple elements can be reported. Each element reported is separated by “|” [ASCII (decimal) 124] | C37: Average | D37: =IFERROR(VLOOKUP(A37,'Unique Values'!$A$2:$B$57,2,FALSE),"") -> Average; Good; Poor; Very Good; Very Poor
... A56: AIR_TIGHTNESS_ENV_EFF | B56: Summary of the performance of this building element, reported in the following format: ‘Description; Energy Efficiency Rating; Environmental Efficiency Rating.’ Both ratings elements are reported on a scale of 1 to 5 (very poor, poor, average, good, very good). Note: where a dwelling has more than one type of this element, multiple elements can be reported. Each element reported is separated by “|” [ASCII (decimal) 124] | C56: Good | D56: =IFERROR(VLOOKUP(A56,'Unique Values'!$A$2:$B$57,2,FALSE),"") -> Average; Good; Very Good
A57: CO2_EMISSIONS_CURRENT | B57: The total annual emissions reduction for the building based upon the calculated energy demand for heating, cooling, lighting, and ventilating the building. (Units: tonnes per year) | C57: 5.5 | D57: =IFERROR(VLOOKUP(A57,'Unique Values'!$A$2:$B$57,2,FALSE),"")
A58: CO2_EMISSIONS_POTENTIAL | B58: Calculation illustrating the total annual emissions reduction for the building if the identified improvement measures are carried out. (Units: tonnes per year) | C58: 2 | D58: =IFERROR(VLOOKUP(A58,'Unique Values'!$A$2:$B$57,2,FALSE),"")
...

Sheet Unique Values
A1: Parameter | B1: Unique_Values
A2: CURRENT_ENERGY_RATING | B2: A; B; C; D; E; F; G
A3: POTENTIAL_ENERGY_RATING | B3: A; B; C; D; E
A4: CURRENT_ENVIRONMENTAL_RATING | B4: A; B; C; D; E; F; G
A5: POTENTIAL_ENVIRONMENTAL_RATING | B5: A; B; C; D; E
A6: WALL_DESCRIPTION | B6: Average thermal transmittance 0.12 W/m¬≤K; Average thermal transmittance 0.13 W/m¬≤K; Average thermal transmittance 0.21 W/m¬≤K; Cavity wall, as built, insulated (assumed); Cavity wall, as built, no insulation (assumed); Cavity wall, as built, partial insulation (assumed); Cavity wall, filled cavity; Cavity wall, with external insulation; Granite or whinstone, as built, insulated (assumed); Granite or whinstone, as built, no insulation (assumed); Granite or whinstone, with internal insulation; Park home wall, as built; Park home wall, with external insulation; Sandstone or limestone, as built, insulated (assumed); Sandstone or limestone, as built, no insulation (assumed); Sandstone or limestone, with internal insulation; Solid brick, as built, no insulation (assumed); System built, as built, insulated (assumed); System built, as built, no insulation (assumed); System built, with external insulation; Timber frame, as built, insulated (assumed); Timber frame, as built, partial insulation (assumed); Timber frame, with additional insulation
A7: WALL_ENERGY_EFF | B7: Average; Good; Poor; Very Good; Very Poor
A8: WALL_ENV_EFF | B8: Average; Good; Poor; Very Good; Very Poor
A9: ROOF_DESCRIPTION | B9: (another dwelling above); Average thermal transmittance 0.10 W/m¬≤K; Average thermal transmittance 0.13 W/m¬≤K; Average thermal transmittance 0.15 W/m¬≤K; Flat, insulated; Flat, insulated (assumed); Flat, limited insulation (assumed); Flat, no insulation (assumed); Pitched, 100 mm loft insulation; Pitched, 150 mm loft insulation; Pitched, 200 mm loft insulation; Pitched, 250 mm loft insulation; Pitched, 270 mm loft insulation; Pitched, 300 mm loft insulation; Pitched, 350 mm loft insulation; Pitched, 400+ mm loft insulation; Pitched, insulated (assumed); Pitched, insulated at rafters; Pitched, limited insulation (assumed); Pitched, no insulation; Pitched, no insulation (assumed); Roof room(s), ceiling insulated; Roof room(s), insulated; Roof room(s), insulated (assumed); Roof room(s), limited insulation (assumed); Roof room(s), no insulation (assumed)
A10: ROOF_ENERGY_EFF | B10: Average; Good; N/A; Poor; Very Good; Very Poor
A11: ROOF_ENV_EFF | B11: Average; Good; N/A; Poor; Very Good; Very Poor
A12: FLOOR_DESCRIPTION | B12: (another dwelling below); Average thermal transmittance 0.12 W/m¬≤K; Average thermal transmittance 0.14 W/m¬≤K; Average thermal transmittance 0.15 W/m¬≤K; Solid, insulated; Solid, insulated (assumed); Solid, no insulation (assumed); Suspended, insulated; Suspended, insulated (assumed); Suspended, limited insulation (assumed); Suspended, no insulation (assumed); To unheated space, insulated (assumed); To unheated space, no insulation (assumed)
... A45: LOCAL_AUTHORITY_LABEL | B45: Stirling
A46: MAINS_GAS_FLAG
A47: MAIN_HEATING_CATEGORY | B47: boiler with radiators or underfloor heating; community heating system; electric storage heaters; heat pump with radiators or underfloor heating; none; room heaters
A48: MAIN_FUEL | B48: biomass; bottled lpg; bulk wood pellets; dual fuel - mineral + wood; electricity; electricity: electricity, unspecified tariff; lpg; mains gas; no heating/hot-water system or data is from a community network; oil
A49: MAIN_HEATING_CONTROLS | B49: 2102.0; 2104.0; 2106.0; 2107.0; 2111.0; 2204.0; 2205.0; 2206.0; 2207.0; 2302.0; 2303.0; 2304.0; 2305.0; 2306.0; 2309.0; 2312.0; 2401.0; 2402.0; 2404.0; 2601.0; 2602.0; 2603.0; 2605.0; 2699.0
A50: MECHANICAL_VENTILATION | B50: mechanical, extract only; mechanical, supply and extract; natural
A51: ENERGY_TARIFF | B51: Single; Unknown; dual; dual (24 hour)
A52: GLAZED_TYPE | B52: double glazing installed before 2002; double glazing installed during or after 2002; double glazing, unknown install date; not defined; triple glazing
A53: SOLAR_WATER_HEATING_FLAG | B53: FALSE
A54: TENURE | B54: owner-occupied; rented (private); rented (social); unknown
A55: TRANSACTION_TYPE | B55: ECO assessment; FiT application; RHI application; marketed sale; new dwelling; non marketed sale; none of the above; rental
A56: BUILT_FORM | B56: Detached; Enclosed End-Terrace; End-Terrace; Mid-Terrace; Semi-Detached
A57: PROPERTY_TYPE | B57: Bungalow; Flat; House; Park home
